Workbook

Sheet 개요
A1: KOMIS 희소금속(Ta·Nb·In·Ga·Hf·Re) 국내 수입현황 2020~2026
A3: 추출일 | B3: 2026-10-22
A4: 출처 1 (국내) | B4: KOMIS 핵심광물지도 > 대한민국 https://www.komis.or.kr/Komis/MnrlMap/Korea (자료출처: 관세청 수출입통계, 공공데이터포털)
A5: 출처 2 (글로벌) | B5: KOMIS 핵심광물지도 > 글로벌 https://www.komis.or.kr/Komis/MnrlMap/Nation (자료출처: UN Comtrade)
A6: 대상 광종 | B6: 탄탈륨(Ta, MNRL0026), 니오븀(Nb, MNRL0007), 인듐(In, MNRL0025), 갈륨(Ga, MNRL0024), 하프늄(Hf, MNRL0040), 레늄(Re, MNRL0042)
A7: 대상 기간 | B7: 2020년~2026년 (연도별). 관세청 데이터의 2026년은 1~9월 누계(KOMIS 기준연도 목록상 2026년 9월까지 집계). 월별 데이터는 2020.01~2026.09.
A8: 단위 | B8: 원자료는 금액 USD, 중량 kg (KOMIS 화면의 천USD·톤 표시는 /1000 환산). 본 파일은 USD·kg 원자료 열과 천USD·톤 수식 열을 함께 제공.
A9: 비중(점유율) | B9: 관세청 시트: 해당 광종·연도 총수입금액(중량) 대비 수식(SUMIFS). UN 시트: KOMIS가 제공한 비중(%) 값을 그대로 수록(소수 → 백분율 서식).
A11: 시트 구성
A12: 요약 | B12: 광종×연도별 총수입금액·중량, 전년비, 수출, 수입국 수, 상위 3개 수입국과 금액비중 (전부 수식, '관세청_연도별_국가' 참조)
A13: 요약_매트릭스 | B13: 광종(행)×연도(열) 매트릭스: 수입금액, 수입중량, 수출금액, 수출중량, 전년비
A14: 관세청_연도별_국가 | B14: [핵심] 광종·연도·국가별 수입/수출 금액·중량, 비중(수식). 모든 수입국 전체(TOP30 제한 없음)
A15: 관세청_연도별_총계(API) | B15: KOMIS '수입규모 추이' 차트 API가 돌려준 연도별 총계 (요약 시트 SUMIFS와 교차검증용, 값 일치 확인)
A16: 관세청_HS코드별_국가 / _총계 | B16: 관세청 HS 10자리 코드별(광석·괴·가루·스크랩·기타 등) 국가별 수입/수출 및 연도별 총계 매트릭스
A17: 관세청_생산품유형별_국가 / _총계 | B17: KOMIS 물질흐름 분류(기초원료/기초금속/가공금속/스크랩)별 국가별 수입/수출 및 연도별 총계
A18: 관세청_월별_국가 / _총계 | B18: 2020.01~2026.09 월별 국가별 수입/수출, 광종별 월별 총계 매트릭스
A19: 관세청_전년대비증가TOP5 | B19: KOMIS '전년대비 교역증가 TOP5' API 결과 (최근 5개년 2021~2025 수입금액, 2025년 증가율). 조회연도와 무관하게 동일값 반환됨
A20: UN_수출국→한국_연도별 | B20: UN Comtrade 기준 한국 수입(수출국별) 금액·중량·비중 (2020~2024, 2025 이후 미집계)
A21: UN_HS6별_수출국→한국 | B21: UN HS 6자리별 수출국→한국 수입 현황
A22: UN_수출국별_추이(한국수입) | B22: 수출국별 연도별 한국향 수출액 추이 (KOMIS 차트 API)
A23: UN_한국→수입국_연도별(수출) | B23: UN Comtrade 기준 한국의 수출(수입국별)
... A27: 코드표 | B27: 광종코드, 관세청 HS10 코드, UN HS6 코드, 생산품 유형, 국가코드
A29: 주의사항
A30: 1 | B30: 관세청(10자리 HS) 데이터는 금속별로 정확히 구분되나, UN Comtrade(6자리 HS)는 811292/811299가 갈륨·게르마늄·인듐·니오븀·바나듐 공용, 261590이 니오븀·탄탈륨·바나듐 광석 공용이므로 UN 시트의 인듐·갈륨 수치는 동일하게 집계되고 니오븀도 타 금속이 섞여 있음. 금속별 분석은 관세청 시트를 사용할 것.
A31: 2 | B31: 관세청 데이터와 UN Comtrade 데이터는 집계 기준(신고국, 환율, 시점)이 달라 소폭 차이가 있음 (예: 탄탈륨 2024 중국 38,126,993 vs 38,155,370 USD).
A32: 3 | B32: KOMIS 글로벌(UN) 데이터는 2025년·2026년이 아직 집계되지 않아 해당 연도 행은 비어 있음.
A33: 4 | B33: '관세청_전년대비증가TOP5'는 KOMIS 화면에서 숨겨진 API로, 검색연도를 바꿔도 최근 5개년 고정값이 반환됨(API 특성).
A34: 5 | B34: 수식 셀은 회색 배경. 원자료 셀은 흰색 배경. 비중은 소수(0.4134)로 저장되고 % 서식으로 표시됨.
A35: 6 | B35: 하프늄·레늄은 2020~2021년 데이터가 관세청·UN 모두 없음(0). HS 2022 개정으로 신설된 전용 코드(8112.31/39, 8112.41/49)만 KOMIS에 매핑되어 있고, 2021년 이전에는 8112.92/99 '기타'에 포함되어 분리 집계가 불가능함.
A36: 7 | B36: UN 글로벌 시트의 2025~2026년 값은 일부 보고국만 반영된 부분 집계이며 한국은 미반영. 국가별 추이 비교는 2024년까지만 유효.
A37: 8 | B37: 원자료(JSON)는 KOMIS 화면이 호출하는 내부 AJAX API(getListKoreaData, getLineChartDataKorea, getTop5TableDataKorea, getListMapKoreaData, getListDataNation, getBarChartDataNation, getListMapNationData)를 그대로 호출해 수집함. 화면의 TOP30 제한 없이 전체 국가를 수록.

Sheet 관세청_연도별_국가
A1: 출처: KOMIS 핵심광물지도-대한민국 (관세청 수출입통계). 금액 USD, 중량 kg 원자료. 천USD/톤/비중 열은 수식. 2026년은 1~9월 누계.
A2: 키 | B2: 광종코드 | C2: 광종 | D2: 원소 | E2: 연도 | F2: 순위(금액) | G2: 국가코드 | H2: 국가명 | I2: 국가명(영문) | J2: 수입금액(USD) | K2: 수입금액(천USD) | L2: 수입중량(kg) | M2: 수입중량(톤) | N2: 수입금액 비중 | O2: 수입중량 비중 | P2: 수출금액(USD) | Q2: 수출금액(천USD) | R2: 수출중량(kg) | S2: 수출중량(톤) | T2: 수출금액 비중 | U2: 수출중량 비중 | V2: KOMIS 총수입금액(USD) | W2: KOMIS 총수입중량(kg) | X2: KOMIS 총수출금액(USD) | Y2: KOMIS 총수출중량(kg) | Z2: 순위(중량) | AA2: 중량키
A3: Ta|2020|1 | B3: MNRL0026 | C3: 탄탈륨 | D3: Ta | E3: 2020 | F3: 1 | G3: US | H3: 미국 | I3: United States of America | J3: 38048316 | K3: =J3/1000 -> 38048.316 | L3: 53903 | M3: =L3/1000 -> 53.903 | N3: =IF(SUMIFS($J$3:$J$20000,$D$3:$D$20000,$D3,$E$3:$E$20000,$E3)=0,0,J3/SUMIFS($J$3:$J$20000,$D$3:$D$20000,$D3,$E$3:$E$20000,$E3)) -> 0.52239586 | O3: =IF(SUMIFS($L$3:$L$20000,$D$3:$D$20000,$D3,$E$3:$E$20000,$E3)=0,0,L3/SUMIFS($L$3:$L$20000,$D$3:$D$20000,$D3,$E$3:$E$20000,$E3)) -> 0.40707009 | P3: 4216993 | Q3: =P3/1000 -> 4216.993 | R3: 45310 | S3: =R3/1000 -> 45.31 | T3: =IF(SUMIFS($P$3:$P$20000,$D$3:$D$20000,$D3,$E$3:$E$20000,$E3)=0,0,P3/SUMIFS($P$3:$P$20000,$D$3:$D$20000,$D3,$E$3:$E$20000,$E3)) -> 0.23504004 | U3: =IF(SUMIFS($R$3:$R$20000,$D$3:$D$20000,$D3,$E$3:$E$20000,$E3)=0,0,R3/SUMIFS($R$3:$R$20000,$D$3:$D$20000,$D3,$E$3:$E$20000,$E3)) -> 0.29529073 | V3: 72834260 | W3: 132417 | X3: 17941594 | Y3: 153442 | Z3: 1 | AA3: Ta|2020|W|1
A4: Ta|2020|2 | B4: MNRL0026 | C4: 탄탈륨 | D4: Ta | E4: 2020 | F4: 2 | G4: JP | H4: 일본 | I4: Japan | J4: 20169356 | K4: =J4/1000 -> 20169.356 | L4: 38809 | M4: =L4/1000 -> 38.809 | N4: =IF(SUMIFS($J$3:$J$20000,$D$3:$D$20000,$D4,$E$3:$E$20000,$E4)=0,0,J4/SUMIFS($J$3:$J$20000,$D$3:$D$20000,$D4,$E$3:$E$20000,$E4)) -> 0.27692127 | O4: =IF(SUMIFS($L$3:$L$20000,$D$3:$D$20000,$D4,$E$3:$E$20000,$E4)=0,0,L4/SUMIFS($L$3:$L$20000,$D$3:$D$20000,$D4,$E$3:$E$20000,$E4)) -> 0.2930817 | P4: 817068 | Q4: =P4/1000 -> 817.068 | R4: 28706 | S4: =R4/1000 -> 28.706 | T4: =IF(SUMIFS($P$3:$P$20000,$D$3:$D$20000,$D4,$E$3:$E$20000,$E4)=0,0,P4/SUMIFS($P$3:$P$20000,$D$3:$D$20000,$D4,$E$3:$E$20000,$E4)) -> 0.045540435 | U4: =IF(SUMIFS($R$3:$R$20000,$D$3:$D$20000,$D4,$E$3:$E$20000,$E4)=0,0,R4/SUMIFS($R$3:$R$20000,$D$3:$D$20000,$D4,$E$3:$E$20000,$E4)) -> 0.18708046 | V4: 72834260 | W4: 132417 | X4: 17941594 | Y4: 153442 | Z4: 2 | AA4: Ta|2020|W|2
A5: Ta|2020|3 | B5: MNRL0026 | C5: 탄탈륨 | D5: Ta | E5: 2020 | F5: 3 | G5: CN | H5: 중국 | I5: China | J5: 13754848 | K5: =J5/1000 -> 13754.848 | L5: 36658 | M5: =L5/1000 -> 36.658 | N5: =IF(SUMIFS($J$3:$J$20000,$D$3:$D$20000,$D5,$E$3:$E$20000,$E5)=0,0,J5/SUMIFS($J$3:$J$20000,$D$3:$D$20000,$D5,$E$3:$E$20000,$E5)) -> 0.18885135 | O5: =IF(SUMIFS($L$3:$L$20000,$D$3:$D$20000,$D5,$E$3:$E$20000,$E5)=0,0,L5/SUMIFS($L$3:$L$20000,$D$3:$D$20000,$D5,$E$3:$E$20000,$E5)) -> 0.27683757 | P5: 5225667 | Q5: =P5/1000 -> 5225.667 | R5: 10566 | S5: =R5/1000 -> 10.566 | T5: =IF(SUMIFS($P$3:$P$20000,$D$3:$D$20000,$D5,$E$3:$E$20000,$E5)=0,0,P5/SUMIFS($P$3:$P$20000,$D$3:$D$20000,$D5,$E$3:$E$20000,$E5)) -> 0.29125991 | U5: =IF(SUMIFS($R$3:$R$20000,$D$3:$D$20000,$D5,$E$3:$E$20000,$E5)=0,0,R5/SUMIFS($R$3:$R$20000,$D$3:$D$20000,$D5,$E$3:$E$20000,$E5)) -> 0.068859895 | V5: 72834260 | W5: 132417 | X5: 17941594 | Y5: 153442 | Z5: 3 | AA5: Ta|2020|W|3
A6: Ta|2020|4 | B6: MNRL0026 | C6: 탄탈륨 | D6: Ta | E6: 2020 | F6: 4 | G6: AT | H6: 오스트리아 | I6: Austria | J6: 332448 | K6: =J6/1000 -> 332.448 | L6: 327 | M6: =L6/1000 -> 0.327 | N6: =IF(SUMIFS($J$3:$J$20000,$D$3:$D$20000,$D6,$E$3:$E$20000,$E6)=0,0,J6/SUMIFS($J$3:$J$20000,$D$3:$D$20000,$D6,$E$3:$E$20000,$E6)) -> 0.0045644454 | O6: =IF(SUMIFS($L$3:$L$20000,$D$3:$D$20000,$D6,$E$3:$E$20000,$E6)=0,0,L6/SUMIFS($L$3:$L$20000,$D$3:$D$20000,$D6,$E$3:$E$20000,$E6)) -> 0.0024694714 | P6: 0 | Q6: =P6/1000 -> 0 | R6: 0 | S6: =R6/1000 -> 0 | T6: =IF(SUMIFS($P$3:$P$20000,$D$3:$D$20000,$D6,$E$3:$E$20000,$E6)=0,0,P6/SUMIFS($P$3:$P$20000,$D$3:$D$20000,$D6,$E$3:$E$20000,$E6)) -> 0 | U6: =IF(SUMIFS($R$3:$R$20000,$D$3:$D$20000,$D6,$E$3:$E$20000,$E6)=0,0,R6/SUMIFS($R$3:$R$20000,$D$3:$D$20000,$D6,$E$3:$E$20000,$E6)) -> 0 | V6: 72834260 | W6: 132417 | X6: 17941594 | Y6: 153442 | Z6: 7 | AA6: Ta|2020|W|7
A7: Ta|2020|5 | B7: MNRL0026 | C7: 탄탈륨 | D7: Ta | E7: 2020 | F7: 5 | G7: FR | H7: 프랑스 | I7: France | J7: 141346 | K7: =J7/1000 -> 141.346 | L7: 208 | M7: =L7/1000 -> 0.208 | N7: =IF(SUMIFS($J$3:$J$20000,$D$3:$D$20000,$D7,$E$3:$E$20000,$E7)=0,0,J7/SUMIFS($J$3:$J$20000,$D$3:$D$20000,$D7,$E$3:$E$20000,$E7)) -> 0.0019406527 | O7: =IF(SUMIFS($L$3:$L$20000,$D$3:$D$20000,$D7,$E$3:$E$20000,$E7)=0,0,L7/SUMIFS($L$3:$L$20000,$D$3:$D$20000,$D7,$E$3:$E$20000,$E7)) -> 0.0015707953 | P7: 75660 | Q7: =P7/1000 -> 75.66 | R7: 107 | S7: =R7/1000 -> 0.107 | T7: =IF(SUMIFS($P$3:$P$20000,$D$3:$D$20000,$D7,$E$3:$E$20000,$E7)=0,0,P7/SUMIFS($P$3:$P$20000,$D$3:$D$20000,$D7,$E$3:$E$20000,$E7)) -> 0.0042170166 | U7: =IF(SUMIFS($R$3:$R$20000,$D$3:$D$20000,$D7,$E$3:$E$20000,$E7)=0,0,R7/SUMIFS($R$3:$R$20000,$D$3:$D$20000,$D7,$E$3:$E$20000,$E7)) -> 0.00069733189 | V7: 72834260 | W7: 132417 | X7: 17941594 | Y7: 153442 | Z7: 8 | AA7: Ta|2020|W|8
A8: Ta|2020|6 | B8: MNRL0026 | C8: 탄탈륨 | D8: Ta | E8: 2020 | F8: 6 | G8: PH | H8: 필리핀 | I8: Philippines | J8: 105409 | K8: =J8/1000 -> 105.409 | L8: 712 | M8: =L8/1000 -> 0.712 | N8: =IF(SUMIFS($J$3:$J$20000,$D$3:$D$20000,$D8,$E$3:$E$20000,$E8)=0,0,J8/SUMIFS($J$3:$J$20000,$D$3:$D$20000,$D8,$E$3:$E$20000,$E8)) -> 0.0014472447 | O8: =IF(SUMIFS($L$3:$L$20000,$D$3:$D$20000,$D8,$E$3:$E$20000,$E8)=0,0,L8/SUMIFS($L$3:$L$20000,$D$3:$D$20000,$D8,$E$3:$E$20000,$E8)) -> 0.0053769531 | P8: 0 | Q8: =P8/1000 -> 0 | R8: 0 | S8: =R8/1000 -> 0 | T8: =IF(SUMIFS($P$3:$P$20000,$D$3:$D$20000,$D8,$E$3:$E$20000,$E8)=0,0,P8/SUMIFS($P$3:$P$20000,$D$3:$D$20000,$D8,$E$3:$E$20000,$E8)) -> 0 | U8: =IF(SUMIFS($R$3:$R$20000,$D$3:$D$20000,$D8,$E$3:$E$20000,$E8)=0,0,R8/SUMIFS($R$3:$R$20000,$D$3:$D$20000,$D8,$E$3:$E$20000,$E8)) -> 0 | V8: 72834260 | W8: 132417 | X8: 17941594 | Y8: 153442 | Z8: 5 | AA8: Ta|2020|W|5
A9: Ta|2020|7 | B9: MNRL0026 | C9: 탄탈륨 | D9: Ta | E9: 2020 | F9: 7 | G9: RU | H9: 러시아 | I9: Russia | J9: 87500 | K9: =J9/1000 -> 87.5 | L9: 500 | M9: =L9/1000 -> 0.5 | N9: =IF(SUMIFS($J$3:$J$20000,$D$3:$D$20000,$D9,$E$3:$E$20000,$E9)=0,0,J9/SUMIFS($J$3:$J$20000,$D$3:$D$20000,$D9,$E$3:$E$20000,$E9)) -> 0.0012013577 | O9: =IF(SUMIFS($L$3:$L$20000,$D$3:$D$20000,$D9,$E$3:$E$20000,$E9)=0,0,L9/SUMIFS($L$3:$L$20000,$D$3:$D$20000,$D9,$E$3:$E$20000,$E9)) -> 0.0037759502 | P9: 0 | Q9: =P9/1000 -> 0 | R9: 0 | S9: =R9/1000 -> 0 | T9: =IF(SUMIFS($P$3:$P$20000,$D$3:$D$20000,$D9,$E$3:$E$20000,$E9)=0,0,P9/SUMIFS($P$3:$P$20000,$D$3:$D$20000,$D9,$E$3:$E$20000,$E9)) -> 0 | U9: =IF(SUMIFS($R$3:$R$20000,$D$3:$D$20000,$D9,$E$3:$E$20000,$E9)=0,0,R9/SUMIFS($R$3:$R$20000,$D$3:$D$20000,$D9,$E$3:$E$20000,$E9)) -> 0 | V9: 72834260 | W9: 132417 | X9: 17941594 | Y9: 153442 | Z9: 6 | AA9: Ta|2020|W|6
A10: Ta|2020|8 | B10: MNRL0026 | C10: 탄탈륨 | D10: Ta | E10: 2020 | F10: 8 | G10: SG | H10: 싱가포르 | I10: Singapore | J10: 61648 | K10: =J10/1000 -> 61.648 | L10: 1028 | M10: =L10/1000 -> 1.028 | N10: =IF(SUMIFS($J$3:$J$20000,$D$3:$D$20000,$D10,$E$3:$E$20000,$E10)=0,0,J10/SUMIFS($J$3:$J$20000,$D$3:$D$20000,$D10,$E$3:$E$20000,$E10)) -> 0.00084641486 | O10: =IF(SUMIFS($L$3:$L$20000,$D$3:$D$20000,$D10,$E$3:$E$20000,$E10)=0,0,L10/SUMIFS($L$3:$L$20000,$D$3:$D$20000,$D10,$E$3:$E$20000,$E10)) -> 0.0077633536 | P10: 327598 | Q10: =P10/1000 -> 327.598 | R10: 1271 | S10: =R10/1000 -> 1.271 | T10: =IF(SUMIFS($P$3:$P$20000,$D$3:$D$20000,$D10,$E$3:$E$20000,$E10)=0,0,P10/SUMIFS($P$3:$P$20000,$D$3:$D$20000,$D10,$E$3:$E$20000,$E10)) -> 0.018259136 | U10: =IF(SUMIFS($R$3:$R$20000,$D$3:$D$20000,$D10,$E$3:$E$20000,$E10)=0,0,R10/SUMIFS($R$3:$R$20000,$D$3:$D$20000,$D10,$E$3:$E$20000,$E10)) -> 0.0082832601 | V10: 72834260 | W10: 132417 | X10: 17941594 | Y10: 153442 | Z10: 4 | AA10: Ta|2020|W|4
A11: Ta|2020|9 | B11: MNRL0026 | C11: 탄탈륨 | D11: Ta | E11: 2020 | F11: 9 | G11: HK | H11: 홍콩 | I11: Hongkong | J11: 45408 | K11: =J11/1000 -> 45.408 | L11: 63 | M11: =L11/1000 -> 0.063 | N11: =IF(SUMIFS($J$3:$J$20000,$D$3:$D$20000,$D11,$E$3:$E$20000,$E11)=0,0,J11/SUMIFS($J$3:$J$20000,$D$3:$D$20000,$D11,$E$3:$E$20000,$E11)) -> 0.00062344287 | O11: =IF(SUMIFS($L$3:$L$20000,$D$3:$D$20000,$D11,$E$3:$E$20000,$E11)=0,0,L11/SUMIFS($L$3:$L$20000,$D$3:$D$20000,$D11,$E$3:$E$20000,$E11)) -> 0.00047576973 | P11: 636107 | Q11: =P11/1000 -> 636.107 | R11: 12508 | S11: =R11/1000 -> 12.508 | T11: =IF(SUMIFS($P$3:$P$20000,$D$3:$D$20000,$D11,$E$3:$E$20000,$E11)=0,0,P11/SUMIFS($P$3:$P$20000,$D$3:$D$20000,$D11,$E$3:$E$20000,$E11)) -> 0.035454319 | U11: =IF(SUMIFS($R$3:$R$20000,$D$3:$D$20000,$D11,$E$3:$E$20000,$E11)=0,0,R11/SUMIFS($R$3:$R$20000,$D$3:$D$20000,$D11,$E$3:$E$20000,$E11)) -> 0.081516143 | V11: 72834260 | W11: 132417 | X11: 17941594 | Y11: 153442 | Z11: 10 | AA11: Ta|2020|W|10
A12: Ta|2020|10 | B12: MNRL0026 | C12: 탄탈륨 | D12: Ta | E12: 2020 | F12: 10 | G12: DE | H12: 독일 | I12: Germany | J12: 33923 | K12: =J12/1000 -> 33.923 | L12: 114 | M12: =L12/1000 -> 0.114 | N12: =IF(SUMIFS($J$3:$J$20000,$D$3:$D$20000,$D12,$E$3:$E$20000,$E12)=0,0,J12/SUMIFS($J$3:$J$20000,$D$3:$D$20000,$D12,$E$3:$E$20000,$E12)) -> 0.00046575609 | O12: =IF(SUMIFS($L$3:$L$20000,$D$3:$D$20000,$D12,$E$3:$E$20000,$E12)=0,0,L12/SUMIFS($L$3:$L$20000,$D$3:$D$20000,$D12,$E$3:$E$20000,$E12)) -> 0.00086091665 | P12: 1062623 | Q12: =P12/1000 -> 1062.623 | R12: 9141 | S12: =R12/1000 -> 9.141 | T12: =IF(SUMIFS($P$3:$P$20000,$D$3:$D$20000,$D12,$E$3:$E$20000,$E12)=0,0,P12/SUMIFS($P$3:$P$20000,$D$3:$D$20000,$D12,$E$3:$E$20000,$E12)) -> 0.059226789 | U12: =IF(SUMIFS($R$3:$R$20000,$D$3:$D$20000,$D12,$E$3:$E$20000,$E12)=0,0,R12/SUMIFS($R$3:$R$20000,$D$3:$D$20000,$D12,$E$3:$E$20000,$E12)) -> 0.059572998 | V12: 72834260 | W12: 132417 | X12: 17941594 | Y12: 153442 | Z12: 9 | AA12: Ta|2020|W|9
A13: Ta|2020|11 | B13: MNRL0026 | C13: 탄탈륨 | D13: Ta | E13: 2020 | F13: 11 | G13: TW | H13: 대만 | I13: Taiwan | J13: 12081 | K13: =J13/1000 -> 12.081 | L13: 24 | M13: =L13/1000 -> 0.024 | N13: =IF(SUMIFS($J$3:$J$20000,$D$3:$D$20000,$D13,$E$3:$E$20000,$E13)=0,0,J13/SUMIFS($J$3:$J$20000,$D$3:$D$20000,$D13,$E$3:$E$20000,$E13)) -> 0.00016586974 | O13: =IF(SUMIFS($L$3:$L$20000,$D$3:$D$20000,$D13,$E$3:$E$20000,$E13)=0,0,L13/SUMIFS($L$3:$L$20000,$D$3:$D$20000,$D13,$E$3:$E$20000,$E13)) -> 0.00018124561 | P13: 2418162 | Q13: =P13/1000 -> 2418.162 | R13: 23571 | S13: =R13/1000 -> 23.571 | T13: =IF(SUMIFS($P$3:$P$20000,$D$3:$D$20000,$D13,$E$3:$E$20000,$E13)=0,0,P13/SUMIFS($P$3:$P$20000,$D$3:$D$20000,$D13,$E$3:$E$20000,$E13)) -> 0.13477966 | U13: =IF(SUMIFS($R$3:$R$20000,$D$3:$D$20000,$D13,$E$3:$E$20000,$E13)=0,0,R13/SUMIFS($R$3:$R$20000,$D$3:$D$20000,$D13,$E$3:$E$20000,$E13)) -> 0.15361505 | V13: 72834260 | W13: 132417 | X13: 17941594 | Y13: 153442 | Z13: 12 | AA13: Ta|2020|W|12
A14: Ta|2020|12 | B14: MNRL0026 | C14: 탄탈륨 | D14: Ta | E14: 2020 | F14: 12 | G14: CH | H14: 스위스 | I14: Swiss | J14: 11956 | K14: =J14/1000 -> 11.956 | L14: 5 | M14: =L14/1000 -> 0.005 | N14: =IF(SUMIFS($J$3:$J$20000,$D$3:$D$20000,$D14,$E$3:$E$20000,$E14)=0,0,J14/SUMIFS($J$3:$J$20000,$D$3:$D$20000,$D14,$E$3:$E$20000,$E14)) -> 0.00016415352 | O14: =IF(SUMIFS($L$3:$L$20000,$D$3:$D$20000,$D14,$E$3:$E$20000,$E14)=0,0,L14/SUMIFS($L$3:$L$20000,$D$3:$D$20000,$D14,$E$3:$E$20000,$E14)) -> 3.7759502e-05 | P14: 0 | Q14: =P14/1000 -> 0 | R14: 0 | S14: =R14/1000 -> 0 | T14: =IF(SUMIFS($P$3:$P$20000,$D$3:$D$20000,$D14,$E$3:$E$20000,$E14)=0,0,P14/SUMIFS($P$3:$P$20000,$D$3:$D$20000,$D14,$E$3:$E$20000,$E14)) -> 0 | U14: =IF(SUMIFS($R$3:$R$20000,$D$3:$D$20000,$D14,$E$3:$E$20000,$E14)=0,0,R14/SUMIFS($R$3:$R$20000,$D$3:$D$20000,$D14,$E$3:$E$20000,$E14)) -> 0 | V14: 72834260 | W14: 132417 | X14: 17941594 | Y14: 153442 | Z14: 16 | AA14: Ta|2020|W|16
... A16: Ta|2020|14 | B16: MNRL0026 | C16: 탄탈륨 | D16: Ta | E16: 2020 | F16: 14 | G16: GB | H16: 영국 | I16: United Kingdom | J16: 8708 | K16: =J16/1000 -> 8.708 | L16: 6 | M16: =L16/1000 -> 0.006 | N16: =IF(SUMIFS($J$3:$J$20000,$D$3:$D$20000,$D16,$E$3:$E$20000,$E16)=0,0,J16/SUMIFS($J$3:$J$20000,$D$3:$D$20000,$D16,$E$3:$E$20000,$E16)) -> 0.00011955912 | O16: =IF(SUMIFS($L$3:$L$20000,$D$3:$D$20000,$D16,$E$3:$E$20000,$E16)=0,0,L16/SUMIFS($L$3:$L$20000,$D$3:$D$20000,$D16,$E$3:$E$20000,$E16)) -> 4.5311403e-05 | P16: 44552 | Q16: =P16/1000 -> 44.552 | R16: 221 | S16: =R16/1000 -> 0.221 | T16: =IF(SUMIFS($P$3:$P$20000,$D$3:$D$20000,$D16,$E$3:$E$20000,$E16)=0,0,P16/SUMIFS($P$3:$P$20000,$D$3:$D$20000,$D16,$E$3:$E$20000,$E16)) -> 0.0024831684 | U16: =IF(SUMIFS($R$3:$R$20000,$D$3:$D$20000,$D16,$E$3:$E$20000,$E16)=0,0,R16/SUMIFS($R$3:$R$20000,$D$3:$D$20000,$D16,$E$3:$E$20000,$E16)) -> 0.0014402836 | V16: 72834260 | W16: 132417 | X16: 17941594 | Y16: 153442 | Z16: 15 | AA16: Ta|2020|W|15
A17: Ta|2020|15 | B17: MNRL0026 | C17: 탄탈륨 | D17: Ta | E17: 2020 | F17: 15 | G17: BD | H17: 방글라데시 | J17: 4661 | K17: =J17/1000 -> 4.661 | L17: 31 | M17: =L17/1000 -> 0.031 | N17: =IF(SUMIFS($J$3:$J$20000,$D$3:$D$20000,$D17,$E$3:$E$20000,$E17)=0,0,J17/SUMIFS($J$3:$J$20000,$D$3:$D$20000,$D17,$E$3:$E$20000,$E17)) -> 6.3994609e-05 | O17: =IF(SUMIFS($L$3:$L$20000,$D$3:$D$20000,$D17,$E$3:$E$20000,$E17)=0,0,L17/SUMIFS($L$3:$L$20000,$D$3:$D$20000,$D17,$E$3:$E$20000,$E17)) -> 0.00023410891 | P17: 0 | Q17: =P17/1000 -> 0 | R17: 0 | S17: =R17/1000 -> 0 | T17: =IF(SUMIFS($P$3:$P$20000,$D$3:$D$20000,$D17,$E$3:$E$20000,$E17)=0,0,P17/SUMIFS($P$3:$P$20000,$D$3:$D$20000,$D17,$E$3:$E$20000,$E17)) -> 0 | U17: =IF(SUMIFS($R$3:$R$20000,$D$3:$D$20000,$D17,$E$3:$E$20000,$E17)=0,0,R17/SUMIFS($R$3:$R$20000,$D$3:$D$20000,$D17,$E$3:$E$20000,$E17)) -> 0 | V17: 72834260 | W17: 132417 | X17: 17941594 | Y17: 153442 | Z17: 11 | AA17: Ta|2020|W|11
A18: Ta|2020|16 | B18: MNRL0026 | C18: 탄탈륨 | D18: Ta | E18: 2020 | F18: 16 | G18: NL | H18: 네덜란드 | I18: Netherlands | J18: 3650 | K18: =J18/1000 -> 3.65 | L18: 0 | M18: =L18/1000 -> 0 | N18: =IF(SUMIFS($J$3:$J$20000,$D$3:$D$20000,$D18,$E$3:$E$20000,$E18)=0,0,J18/SUMIFS($J$3:$J$20000,$D$3:$D$20000,$D18,$E$3:$E$20000,$E18)) -> 5.0113779e-05 | O18: =IF(SUMIFS($L$3:$L$20000,$D$3:$D$20000,$D18,$E$3:$E$20000,$E18)=0,0,L18/SUMIFS($L$3:$L$20000,$D$3:$D$20000,$D18,$E$3:$E$20000,$E18)) -> 0 | P18: 0 | Q18: =P18/1000 -> 0 | R18: 0 | S18: =R18/1000 -> 0 | T18: =IF(SUMIFS($P$3:$P$20000,$D$3:$D$20000,$D18,$E$3:$E$20000,$E18)=0,0,P18/SUMIFS($P$3:$P$20000,$D$3:$D$20000,$D18,$E$3:$E$20000,$E18)) -> 0 | U18: =IF(SUMIFS($R$3:$R$20000,$D$3:$D$20000,$D18,$E$3:$E$20000,$E18)=0,0,R18/SUMIFS($R$3:$R$20000,$D$3:$D$20000,$D18,$E$3:$E$20000,$E18)) -> 0 | V18: 72834260 | W18: 132417 | X18: 17941594 | Y18: 153442 | Z18: 20 | AA18: Ta|2020|W|20
A19: Ta|2020|17 | B19: MNRL0026 | C19: 탄탈륨 | D19: Ta | E19: 2020 | F19: 17 | G19: KN | H19: 세인트키츠네비스 | J19: 912 | K19: =J19/1000 -> 0.912 | L19: 2 | M19: =L19/1000 -> 0.002 | N19: =IF(SUMIFS($J$3:$J$20000,$D$3:$D$20000,$D19,$E$3:$E$20000,$E19)=0,0,J19/SUMIFS($J$3:$J$20000,$D$3:$D$20000,$D19,$E$3:$E$20000,$E19)) -> 1.252158e-05 | O19: =IF(SUMIFS($L$3:$L$20000,$D$3:$D$20000,$D19,$E$3:$E$20000,$E19)=0,0,L19/SUMIFS($L$3:$L$20000,$D$3:$D$20000,$D19,$E$3:$E$20000,$E19)) -> 1.5103801e-05 | P19: 0 | Q19: =P19/1000 -> 0 | R19: 0 | S19: =R19/1000 -> 0 | T19: =IF(SUMIFS($P$3:$P$20000,$D$3:$D$20000,$D19,$E$3:$E$20000,$E19)=0,0,P19/SUMIFS($P$3:$P$20000,$D$3:$D$20000,$D19,$E$3:$E$20000,$E19)) -> 0 | U19: =IF(SUMIFS($R$3:$R$20000,$D$3:$D$20000,$D19,$E$3:$E$20000,$E19)=0,0,R19/SUMIFS($R$3:$R$20000,$D$3:$D$20000,$D19,$E$3:$E$20000,$E19)) -> 0 | V19: 72834260 | W19: 132417 | X19: 17941594 | Y19: 153442 | Z19: 18 | AA19: Ta|2020|W|18
A20: Ta|2020|18 | B20: MNRL0026 | C20: 탄탈륨 | D20: Ta | E20: 2020 | F20: 18 | G20: IN | H20: 인도 | J20: 790 | K20: =J20/1000 -> 0.79 | L20: 4 | M20: =L20/1000 -> 0.004 | N20: =IF(SUMIFS($J$3:$J$20000,$D$3:$D$20000,$D20,$E$3:$E$20000,$E20)=0,0,J20/SUMIFS($J$3:$J$20000,$D$3:$D$20000,$D20,$E$3:$E$20000,$E20)) -> 1.0846544e-05 | O20: =IF(SUMIFS($L$3:$L$20000,$D$3:$D$20000,$D20,$E$3:$E$20000,$E20)=0,0,L20/SUMIFS($L$3:$L$20000,$D$3:$D$20000,$D20,$E$3:$E$20000,$E20)) -> 3.0207602e-05 | P20: 468 | Q20: =P20/1000 -> 0.468 | R20: 1 | S20: =R20/1000 -> 0.001 | T20: =IF(SUMIFS($P$3:$P$20000,$D$3:$D$20000,$D20,$E$3:$E$20000,$E20)=0,0,P20/SUMIFS($P$3:$P$20000,$D$3:$D$20000,$D20,$E$3:$E$20000,$E20)) -> 2.6084639e-05 | U20: =IF(SUMIFS($R$3:$R$20000,$D$3:$D$20000,$D20,$E$3:$E$20000,$E20)=0,0,R20/SUMIFS($R$3:$R$20000,$D$3:$D$20000,$D20,$E$3:$E$20000,$E20)) -> 6.5171205e-06 | V20: 72834260 | W20: 132417 | X20: 17941594 | Y20: 153442 | Z20: 17 | AA20: Ta|2020|W|17
A21: Ta|2020|19 | B21: MNRL0026 | C21: 탄탈륨 | D21: Ta | E21: 2020 | F21: 19 | G21: AD | H21: 안도라 | J21: 370 | K21: =J21/1000 -> 0.37 | L21: 1 | M21: =L21/1000 -> 0.001 | N21: =IF(SUMIFS($J$3:$J$20000,$D$3:$D$20000,$D21,$E$3:$E$20000,$E21)=0,0,J21/SUMIFS($J$3:$J$20000,$D$3:$D$20000,$D21,$E$3:$E$20000,$E21)) -> 5.0800269e-06 | O21: =IF(SUMIFS($L$3:$L$20000,$D$3:$D$20000,$D21,$E$3:$E$20000,$E21)=0,0,L21/SUMIFS($L$3:$L$20000,$D$3:$D$20000,$D21,$E$3:$E$20000,$E21)) -> 7.5519004e-06 | P21: 0 | Q21: =P21/1000 -> 0 | R21: 0 | S21: =R21/1000 -> 0 | T21: =IF(SUMIFS($P$3:$P$20000,$D$3:$D$20000,$D21,$E$3:$E$20000,$E21)=0,0,P21/SUMIFS($P$3:$P$20000,$D$3:$D$20000,$D21,$E$3:$E$20000,$E21)) -> 0 | U21: =IF(SUMIFS($R$3:$R$20000,$D$3:$D$20000,$D21,$E$3:$E$20000,$E21)=0,0,R21/SUMIFS($R$3:$R$20000,$D$3:$D$20000,$D21,$E$3:$E$20000,$E21)) -> 0 | V21: 72834260 | W21: 132417 | X21: 17941594 | Y21: 153442 | Z21: 19 | AA21: Ta|2020|W|19
A22: Ta|2020|20 | B22: MNRL0026 | C22: 탄탈륨 | D22: Ta | E22: 2020 | F22: 20 | G22: LR | H22: 라이베리아 | J22: 296 | K22: =J22/1000 -> 0.296 | L22: 10 | M22: =L22/1000 -> 0.01 | N22: =IF(SUMIFS($J$3:$J$20000,$D$3:$D$20000,$D22,$E$3:$E$20000,$E22)=0,0,J22/SUMIFS($J$3:$J$20000,$D$3:$D$20000,$D22,$E$3:$E$20000,$E22)) -> 4.0640215e-06 | O22: =IF(SUMIFS($L$3:$L$20000,$D$3:$D$20000,$D22,$E$3:$E$20000,$E22)=0,0,L22/SUMIFS($L$3:$L$20000,$D$3:$D$20000,$D22,$E$3:$E$20000,$E22)) -> 7.5519004e-05 | P22: 0 | Q22: =P22/1000 -> 0 | R22: 0 | S22: =R22/1000 -> 0 | T22: =IF(SUMIFS($P$3:$P$20000,$D$3:$D$20000,$D22,$E$3:$E$20000,$E22)=0,0,P22/SUMIFS($P$3:$P$20000,$D$3:$D$20000,$D22,$E$3:$E$20000,$E22)) -> 0 | U22: =IF(SUMIFS($R$3:$R$20000,$D$3:$D$20000,$D22,$E$3:$E$20000,$E22)=0,0,R22/SUMIFS($R$3:$R$20000,$D$3:$D$20000,$D22,$E$3:$E$20000,$E22)) -> 0 | V22: 72834260 | W22: 132417 | X22: 17941594 | Y22: 153442 | Z22: 14 | AA22: Ta|2020|W|14
A23: Ta|2020|21 | B23: MNRL0026 | C23: 탄탈륨 | D23: Ta | E23: 2020 | F23: 21 | G23: KZ | H23: 카자흐스탄 | I23: Kazakhstan | J23: 0 | K23: =J23/1000 -> 0 | L23: 0 | M23: =L23/1000 -> 0 | N23: =IF(SUMIFS($J$3:$J$20000,$D$3:$D$20000,$D23,$E$3:$E$20000,$E23)=0,0,J23/SUMIFS($J$3:$J$20000,$D$3:$D$20000,$D23,$E$3:$E$20000,$E23)) -> 0 | O23: =IF(SUMIFS($L$3:$L$20000,$D$3:$D$20000,$D23,$E$3:$E$20000,$E23)=0,0,L23/SUMIFS($L$3:$L$20000,$D$3:$D$20000,$D23,$E$3:$E$20000,$E23)) -> 0 | P23: 3092218 | Q23: =P23/1000 -> 3092.218 | R23: 14538 | S23: =R23/1000 -> 14.538 | T23: =IF(SUMIFS($P$3:$P$20000,$D$3:$D$20000,$D23,$E$3:$E$20000,$E23)=0,0,P23/SUMIFS($P$3:$P$20000,$D$3:$D$20000,$D23,$E$3:$E$20000,$E23)) -> 0.17234912 | U23: =IF(SUMIFS($R$3:$R$20000,$D$3:$D$20000,$D23,$E$3:$E$20000,$E23)=0,0,R23/SUMIFS($R$3:$R$20000,$D$3:$D$20000,$D23,$E$3:$E$20000,$E23)) -> 0.094745897 | V23: 72834260 | W23: 132417 | X23: 17941594 | Y23: 153442 | Z23: 21 | AA23: Ta|2020|W|21
A24: Ta|2020|22 | B24: MNRL0026 | C24: 탄탈륨 | D24: Ta | E24: 2020 | F24: 22 | G24: TH | H24: 태국 | J24: 0 | K24: =J24/1000 -> 0 | L24: 0 | M24: =L24/1000 -> 0 | N24: =IF(SUMIFS($J$3:$J$20000,$D$3:$D$20000,$D24,$E$3:$E$20000,$E24)=0,0,J24/SUMIFS($J$3:$J$20000,$D$3:$D$20000,$D24,$E$3:$E$20000,$E24)) -> 0 | O24: =IF(SUMIFS($L$3:$L$20000,$D$3:$D$20000,$D24,$E$3:$E$20000,$E24)=0,0,L24/SUMIFS($L$3:$L$20000,$D$3:$D$20000,$D24,$E$3:$E$20000,$E24)) -> 0 | P24: 503 | Q24: =P24/1000 -> 0.503 | R24: 1 | S24: =R24/1000 -> 0.001 | T24: =IF(SUMIFS($P$3:$P$20000,$D$3:$D$20000,$D24,$E$3:$E$20000,$E24)=0,0,P24/SUMIFS($P$3:$P$20000,$D$3:$D$20000,$D24,$E$3:$E$20000,$E24)) -> 2.8035413e-05 | U24: =IF(SUMIFS($R$3:$R$20000,$D$3:$D$20000,$D24,$E$3:$E$20000,$E24)=0,0,R24/SUMIFS($R$3:$R$20000,$D$3:$D$20000,$D24,$E$3:$E$20000,$E24)) -> 6.5171205e-06 | V24: 72834260 | W24: 132417 | X24: 17941594 | Y24: 153442 | Z24: 22 | AA24: Ta|2020|W|22
A25: Ta|2020|23 | B25: MNRL0026 | C25: 탄탈륨 | D25: Ta | E25: 2020 | F25: 23 | G25: EG | H25: 이집트 | J25: 0 | K25: =J25/1000 -> 0 | L25: 0 | M25: =L25/1000 -> 0 | N25: =IF(SUMIFS($J$3:$J$20000,$D$3:$D$20000,$D25,$E$3:$E$20000,$E25)=0,0,J25/SUMIFS($J$3:$J$20000,$D$3:$D$20000,$D25,$E$3:$E$20000,$E25)) -> 0 | O25: =IF(SUMIFS($L$3:$L$20000,$D$3:$D$20000,$D25,$E$3:$E$20000,$E25)=0,0,L25/SUMIFS($L$3:$L$20000,$D$3:$D$20000,$D25,$E$3:$E$20000,$E25)) -> 0 | P25: 300 | Q25: =P25/1000 -> 0.3 | R25: 0 | S25: =R25/1000 -> 0 | T25: =IF(SUMIFS($P$3:$P$20000,$D$3:$D$20000,$D25,$E$3:$E$20000,$E25)=0,0,P25/SUMIFS($P$3:$P$20000,$D$3:$D$20000,$D25,$E$3:$E$20000,$E25)) -> 1.6720922e-05 | U25: =IF(SUMIFS($R$3:$R$20000,$D$3:$D$20000,$D25,$E$3:$E$20000,$E25)=0,0,R25/SUMIFS($R$3:$R$20000,$D$3:$D$20000,$D25,$E$3:$E$20000,$E25)) -> 0 | V25: 72834260 | W25: 132417 | X25: 17941594 | Y25: 153442 | Z25: 23 | AA25: Ta|2020|W|23
A26: Ta|2020|24 | B26: MNRL0026 | C26: 탄탈륨 | D26: Ta | E26: 2020 | F26: 24 | G26: EE | H26: 에스토니아 | I26: Estonia | J26: 0 | K26: =J26/1000 -> 0 | L26: 0 | M26: =L26/1000 -> 0 | N26: =IF(SUMIFS($J$3:$J$20000,$D$3:$D$20000,$D26,$E$3:$E$20000,$E26)=0,0,J26/SUMIFS($J$3:$J$20000,$D$3:$D$20000,$D26,$E$3:$E$20000,$E26)) -> 0 | O26: =IF(SUMIFS($L$3:$L$20000,$D$3:$D$20000,$D26,$E$3:$E$20000,$E26)=0,0,L26/SUMIFS($L$3:$L$20000,$D$3:$D$20000,$D26,$E$3:$E$20000,$E26)) -> 0 | P26: 20098 | Q26: =P26/1000 -> 20.098 | R26: 7498 | S26: =R26/1000 -> 7.498 | T26: =IF(SUMIFS($P$3:$P$20000,$D$3:$D$20000,$D26,$E$3:$E$20000,$E26)=0,0,P26/SUMIFS($P$3:$P$20000,$D$3:$D$20000,$D26,$E$3:$E$20000,$E26)) -> 0.0011201903 | U26: =IF(SUMIFS($R$3:$R$20000,$D$3:$D$20000,$D26,$E$3:$E$20000,$E26)=0,0,R26/SUMIFS($R$3:$R$20000,$D$3:$D$20000,$D26,$E$3:$E$20000,$E26)) -> 0.048865369 | V26: 72834260 | W26: 132417 | X26: 17941594 | Y26: 153442 | Z26: 24 | AA26: Ta|2020|W|24
A27: Ta|2020|25 | B27: MNRL0026 | C27: 탄탈륨 | D27: Ta | E27: 2020 | F27: 25 | G27: VN | H27: 베트남 | I27: Vietnam | J27: 0 | K27: =J27/1000 -> 0 | L27: 0 | M27: =L27/1000 -> 0 | N27: =IF(SUMIFS($J$3:$J$20000,$D$3:$D$20000,$D27,$E$3:$E$20000,$E27)=0,0,J27/SUMIFS($J$3:$J$20000,$D$3:$D$20000,$D27,$E$3:$E$20000,$E27)) -> 0 | O27: =IF(SUMIFS($L$3:$L$20000,$D$3:$D$20000,$D27,$E$3:$E$20000,$E27)=0,0,L27/SUMIFS($L$3:$L$20000,$D$3:$D$20000,$D27,$E$3:$E$20000,$E27)) -> 0 | P27: 3577 | Q27: =P27/1000 -> 3.577 | R27: 3 | S27: =R27/1000 -> 0.003 | T27: =IF(SUMIFS($P$3:$P$20000,$D$3:$D$20000,$D27,$E$3:$E$20000,$E27)=0,0,P27/SUMIFS($P$3:$P$20000,$D$3:$D$20000,$D27,$E$3:$E$20000,$E27)) -> 0.00019936913 | U27: =IF(SUMIFS($R$3:$R$20000,$D$3:$D$20000,$D27,$E$3:$E$20000,$E27)=0,0,R27/SUMIFS($R$3:$R$20000,$D$3:$D$20000,$D27,$E$3:$E$20000,$E27)) -> 1.9551361e-05 | V27: 72834260 | W27: 132417 | X27: 17941594 | Y27: 153442 | Z27: 25 | AA27: Ta|2020|W|25
A28: Ta|2021|1 | B28: MNRL0026 | C28: 탄탈륨 | D28: Ta | E28: 2021 | F28: 1 | G28: US | H28: 미국 | I28: United States of America | J28: 52972982 | K28: =J28/1000 -> 52972.982 | L28: 75157 | M28: =L28/1000 -> 75.157 | N28: =IF(SUMIFS($J$3:$J$20000,$D$3:$D$20000,$D28,$E$3:$E$20000,$E28)=0,0,J28/SUMIFS($J$3:$J$20000,$D$3:$D$20000,$D28,$E$3:$E$20000,$E28)) -> 0.5809872 | O28: =IF(SUMIFS($L$3:$L$20000,$D$3:$D$20000,$D28,$E$3:$E$20000,$E28)=0,0,L28/SUMIFS($L$3:$L$20000,$D$3:$D$20000,$D28,$E$3:$E$20000,$E28)) -> 0.44971876 | P28: 6320646 | Q28: =P28/1000 -> 6320.646 | R28: 65158 | S28: =R28/1000 -> 65.158 | T28: =IF(SUMIFS($P$3:$P$20000,$D$3:$D$20000,$D28,$E$3:$E$20000,$E28)=0,0,P28/SUMIFS($P$3:$P$20000,$D$3:$D$20000,$D28,$E$3:$E$20000,$E28)) -> 0.24352657 | U28: =IF(SUMIFS($R$3:$R$20000,$D$3:$D$20000,$D28,$E$3:$E$20000,$E28)=0,0,R28/SUMIFS($R$3:$R$20000,$D$3:$D$20000,$D28,$E$3:$E$20000,$E28)) -> 0.32907582 | V28: 91177537 | W28: 167120 | X28: 25954646 | Y28: 198003 | Z28: 1 | AA28: Ta|2021|W|1
A29: Ta|2021|2 | B29: MNRL0026 | C29: 탄탈륨 | D29: Ta | E29: 2021 | F29: 2 | G29: JP | H29: 일본 | I29: Japan | J29: 24261180 | K29: =J29/1000 -> 24261.18 | L29: 55676 | M29: =L29/1000 -> 55.676 | N29: =IF(SUMIFS($J$3:$J$20000,$D$3:$D$20000,$D29,$E$3:$E$20000,$E29)=0,0,J29/SUMIFS($J$3:$J$20000,$D$3:$D$20000,$D29,$E$3:$E$20000,$E29)) -> 0.26608725 | O29: =IF(SUMIFS($L$3:$L$20000,$D$3:$D$20000,$D29,$E$3:$E$20000,$E29)=0,0,L29/SUMIFS($L$3:$L$20000,$D$3:$D$20000,$D29,$E$3:$E$20000,$E29)) -> 0.33314983 | P29: 1030181 | Q29: =P29/1000 -> 1030.181 | R29: 16661 | S29: =R29/1000 -> 16.661 | T29: =IF(SUMIFS($P$3:$P$20000,$D$3:$D$20000,$D29,$E$3:$E$20000,$E29)=0,0,P29/SUMIFS($P$3:$P$20000,$D$3:$D$20000,$D29,$E$3:$E$20000,$E29)) -> 0.039691584 | U29: =IF(SUMIFS($R$3:$R$20000,$D$3:$D$20000,$D29,$E$3:$E$20000,$E29)=0,0,R29/SUMIFS($R$3:$R$20000,$D$3:$D$20000,$D29,$E$3:$E$20000,$E29)) -> 0.08414519 | V29: 91177537 | W29: 167120 | X29: 25954646 | Y29: 198003 | Z29: 2 | AA29: Ta|2021|W|2
A30: Ta|2021|3 | B30: MNRL0026 | C30: 탄탈륨 | D30: Ta | E30: 2021 | F30: 3 | G30: CN | H30: 중국 | I30: China | J30: 13042770 | K30: =J30/1000 -> 13042.77 | L30: 33132 | M30: =L30/1000 -> 33.132 | N30: =IF(SUMIFS($J$3:$J$20000,$D$3:$D$20000,$D30,$E$3:$E$20000,$E30)=0,0,J30/SUMIFS($J$3:$J$20000,$D$3:$D$20000,$D30,$E$3:$E$20000,$E30)) -> 0.14304806 | O30: =IF(SUMIFS($L$3:$L$20000,$D$3:$D$20000,$D30,$E$3:$E$20000,$E30)=0,0,L30/SUMIFS($L$3:$L$20000,$D$3:$D$20000,$D30,$E$3:$E$20000,$E30)) -> 0.19825275 | P30: 9128440 | Q30: =P30/1000 -> 9128.44 | R30: 22585 | S30: =R30/1000 -> 22.585 | T30: =IF(SUMIFS($P$3:$P$20000,$D$3:$D$20000,$D30,$E$3:$E$20000,$E30)=0,0,P30/SUMIFS($P$3:$P$20000,$D$3:$D$20000,$D30,$E$3:$E$20000,$E30)) -> 0.35170736 | U30: =IF(SUMIFS($R$3:$R$20000,$D$3:$D$20000,$D30,$E$3:$E$20000,$E30)=0,0,R30/SUMIFS($R$3:$R$20000,$D$3:$D$20000,$D30,$E$3:$E$20000,$E30)) -> 0.11406393 | V30: 91177537 | W30: 167120 | X30: 25954646 | Y30: 198003 | Z30: 3 | AA30: Ta|2021|W|3
A31: Ta|2021|4 | B31: MNRL0026 | C31: 탄탈륨 | D31: Ta | E31: 2021 | F31: 4 | G31: AT | H31: 오스트리아 | I31: Austria | J31: 262482 | K31: =J31/1000 -> 262.482 | L31: 232 | M31: =L31/1000 -> 0.232 | N31: =IF(SUMIFS($J$3:$J$20000,$D$3:$D$20000,$D31,$E$3:$E$20000,$E31)=0,0,J31/SUMIFS($J$3:$J$20000,$D$3:$D$20000,$D31,$E$3:$E$20000,$E31)) -> 0.0028788012 | O31: =IF(SUMIFS($L$3:$L$20000,$D$3:$D$20000,$D31,$E$3:$E$20000,$E31)=0,0,L31/SUMIFS($L$3:$L$20000,$D$3:$D$20000,$D31,$E$3:$E$20000,$E31)) -> 0.001388224 | P31: 113 | Q31: =P31/1000 -> 0.113 | R31: 0 | S31: =R31/1000 -> 0 | T31: =IF(SUMIFS($P$3:$P$20000,$D$3:$D$20000,$D31,$E$3:$E$20000,$E31)=0,0,P31/SUMIFS($P$3:$P$20000,$D$3:$D$20000,$D31,$E$3:$E$20000,$E31)) -> 4.3537485e-06 | U31: =IF(SUMIFS($R$3:$R$20000,$D$3:$D$20000,$D31,$E$3:$E$20000,$E31)=0,0,R31/SUMIFS($R$3:$R$20000,$D$3:$D$20000,$D31,$E$3:$E$20000,$E31)) -> 0 | V31: 91177537 | W31: 167120 | X31: 25954646 | Y31: 198003 | Z31: 7 | AA31: Ta|2021|W|7
A32: Ta|2021|5 | B32: MNRL0026 | C32: 탄탈륨 | D32: Ta | E32: 2021 | F32: 5 | G32: RU | H32: 러시아 | I32: Russia | J32: 208000 | K32: =J32/1000 -> 208 | L32: 1000 | M32: =L32/1000 -> 1 | N32: =IF(SUMIFS($J$3:$J$20000,$D$3:$D$20000,$D32,$E$3:$E$20000,$E32)=0,0,J32/SUMIFS($J$3:$J$20000,$D$3:$D$20000,$D32,$E$3:$E$20000,$E32)) -> 0.0022812636 | O32: =IF(SUMIFS($L$3:$L$20000,$D$3:$D$20000,$D32,$E$3:$E$20000,$E32)=0,0,L32/SUMIFS($L$3:$L$20000,$D$3:$D$20000,$D32,$E$3:$E$20000,$E32)) -> 0.0059837243 | P32: 0 | Q32: =P32/1000 -> 0 | R32: 0 | S32: =R32/1000 -> 0 | T32: =IF(SUMIFS($P$3:$P$20000,$D$3:$D$20000,$D32,$E$3:$E$20000,$E32)=0,0,P32/SUMIFS($P$3:$P$20000,$D$3:$D$20000,$D32,$E$3:$E$20000,$E32)) -> 0 | U32: =IF(SUMIFS($R$3:$R$20000,$D$3:$D$20000,$D32,$E$3:$E$20000,$E32)=0,0,R32/SUMIFS($R$3:$R$20000,$D$3:$D$20000,$D32,$E$3:$E$20000,$E32)) -> 0 | V32: 91177537 | W32: 167120 | X32: 25954646 | Y32: 198003 | Z32: 4 | AA32: Ta|2021|W|4
A33: Ta|2021|6 | B33: MNRL0026 | C33: 탄탈륨 | D33: Ta | E33: 2021 | F33: 6 | G33: FR | H33: 프랑스 | I33: France | J33: 131922 | K33: =J33/1000 -> 131.922 | L33: 184 | M33: =L33/1000 -> 0.184 | N33: =IF(SUMIFS($J$3:$J$20000,$D$3:$D$20000,$D33,$E$3:$E$20000,$E33)=0,0,J33/SUMIFS($J$3:$J$20000,$D$3:$D$20000,$D33,$E$3:$E$20000,$E33)) -> 0.0014468695 | O33: =IF(SUMIFS($L$3:$L$20000,$D$3:$D$20000,$D33,$E$3:$E$20000,$E33)=0,0,L33/SUMIFS($L$3:$L$20000,$D$3:$D$20000,$D33,$E$3:$E$20000,$E33)) -> 0.0011010053 | P33: 53859 | Q33: =P33/1000 -> 53.859 | R33: 113 | S33: =R33/1000 -> 0.113 | T33: =IF(SUMIFS($P$3:$P$20000,$D$3:$D$20000,$D33,$E$3:$E$20000,$E33)=0,0,P33/SUMIFS($P$3:$P$20000,$D$3:$D$20000,$D33,$E$3:$E$20000,$E33)) -> 0.0020751198 | U33: =IF(SUMIFS($R$3:$R$20000,$D$3:$D$20000,$D33,$E$3:$E$20000,$E33)=0,0,R33/SUMIFS($R$3:$R$20000,$D$3:$D$20000,$D33,$E$3:$E$20000,$E33)) -> 0.00057069842 | V33: 91177537 | W33: 167120 | X33: 25954646 | Y33: 198003 | Z33: 8 | AA33: Ta|2021|W|8
A34: Ta|2021|7 | B34: MNRL0026 | C34: 탄탈륨 | D34: Ta | E34: 2021 | F34: 7 | G34: PH | H34: 필리핀 | I34: Philippines | J34: 91645 | K34: =J34/1000 -> 91.645 | L34: 603 | M34: =L34/1000 -> 0.603 | N34: =IF(SUMIFS($J$3:$J$20000,$D$3:$D$20000,$D34,$E$3:$E$20000,$E34)=0,0,J34/SUMIFS($J$3:$J$20000,$D$3:$D$20000,$D34,$E$3:$E$20000,$E34)) -> 0.001005127 | O34: =IF(SUMIFS($L$3:$L$20000,$D$3:$D$20000,$D34,$E$3:$E$20000,$E34)=0,0,L34/SUMIFS($L$3:$L$20000,$D$3:$D$20000,$D34,$E$3:$E$20000,$E34)) -> 0.0036081857 | P34: 3377 | Q34: =P34/1000 -> 3.377 | R34: 6 | S34: =R34/1000 -> 0.006 | T34: =IF(SUMIFS($P$3:$P$20000,$D$3:$D$20000,$D34,$E$3:$E$20000,$E34)=0,0,P34/SUMIFS($P$3:$P$20000,$D$3:$D$20000,$D34,$E$3:$E$20000,$E34)) -> 0.00013011158 | U34: =IF(SUMIFS($R$3:$R$20000,$D$3:$D$20000,$D34,$E$3:$E$20000,$E34)=0,0,R34/SUMIFS($R$3:$R$20000,$D$3:$D$20000,$D34,$E$3:$E$20000,$E34)) -> 3.0302571e-05 | V34: 91177537 | W34: 167120 | X34: 25954646 | Y34: 198003 | Z34: 6 | AA34: Ta|2021|W|6
A35: Ta|2021|8 | B35: MNRL0026 | C35: 탄탈륨 | D35: Ta | E35: 2021 | F35: 8 | G35: HK | H35: 홍콩 | I35: Hongkong | J35: 43964 | K35: =J35/1000 -> 43.964 | L35: 48 | M35: =L35/1000 -> 0.048 | N35: =IF(SUMIFS($J$3:$J$20000,$D$3:$D$20000,$D35,$E$3:$E$20000,$E35)=0,0,J35/SUMIFS($J$3:$J$20000,$D$3:$D$20000,$D35,$E$3:$E$20000,$E35)) -> 0.00048218017 | O35: =IF(SUMIFS($L$3:$L$20000,$D$3:$D$20000,$D35,$E$3:$E$20000,$E35)=0,0,L35/SUMIFS($L$3:$L$20000,$D$3:$D$20000,$D35,$E$3:$E$20000,$E35)) -> 0.00028721876 | P35: 931848 | Q35: =P35/1000 -> 931.848 | R35: 31998 | S35: =R35/1000 -> 31.998 | T35: =IF(SUMIFS($P$3:$P$20000,$D$3:$D$20000,$D35,$E$3:$E$20000,$E35)=0,0,P35/SUMIFS($P$3:$P$20000,$D$3:$D$20000,$D35,$E$3:$E$20000,$E35)) -> 0.035902936 | U35: =IF(SUMIFS($R$3:$R$20000,$D$3:$D$20000,$D35,$E$3:$E$20000,$E35)=0,0,R35/SUMIFS($R$3:$R$20000,$D$3:$D$20000,$D35,$E$3:$E$20000,$E35)) -> 0.16160361 | V35: 91177537 | W35: 167120 | X35: 25954646 | Y35: 198003 | Z35: 12 | AA35: Ta|2021|W|12
A36: Ta|2021|9 | B36: MNRL0026 | C36: 탄탈륨 | D36: Ta | E36: 2021 | F36: 9 | G36: SG | H36: 싱가포르 | I36: Singapore | J36: 39231 | K36: =J36/1000 -> 39.231 | L36: 738 | M36: =L36/1000 -> 0.738 | N36: =IF(SUMIFS($J$3:$J$20000,$D$3:$D$20000,$D36,$E$3:$E$20000,$E36)=0,0,J36/SUMIFS($J$3:$J$20000,$D$3:$D$20000,$D36,$E$3:$E$20000,$E36)) -> 0.00043027045 | O36: =IF(SUMIFS($L$3:$L$20000,$D$3:$D$20000,$D36,$E$3:$E$20000,$E36)=0,0,L36/SUMIFS($L$3:$L$20000,$D$3:$D$20000,$D36,$E$3:$E$20000,$E36)) -> 0.0044159885 | P36: 316036 | Q36: =P36/1000 -> 316.036 | R36: 1102 | S36: =R36/1000 -> 1.102 | T36: =IF(SUMIFS($P$3:$P$20000,$D$3:$D$20000,$D36,$E$3:$E$20000,$E36)=0,0,P36/SUMIFS($P$3:$P$20000,$D$3:$D$20000,$D36,$E$3:$E$20000,$E36)) -> 0.012176471 | U36: =IF(SUMIFS($R$3:$R$20000,$D$3:$D$20000,$D36,$E$3:$E$20000,$E36)=0,0,R36/SUMIFS($R$3:$R$20000,$D$3:$D$20000,$D36,$E$3:$E$20000,$E36)) -> 0.0055655722 | V36: 91177537 | W36: 167120 | X36: 25954646 | Y36: 198003 | Z36: 5 | AA36: Ta|2021|W|5
A37: Ta|2021|10 | B37: MNRL0026 | C37: 탄탈륨 | D37: Ta | E37: 2021 | F37: 10 | G37: DE | H37: 독일 | I37: Germany | J37: 26678 | K37: =J37/1000 -> 26.678 | L37: 78 | M37: =L37/1000 -> 0.078 | N37: =IF(SUMIFS($J$3:$J$20000,$D$3:$D$20000,$D37,$E$3:$E$20000,$E37)=0,0,J37/SUMIFS($J$3:$J$20000,$D$3:$D$20000,$D37,$E$3:$E$20000,$E37)) -> 0.000292594 | O37: =IF(SUMIFS($L$3:$L$20000,$D$3:$D$20000,$D37,$E$3:$E$20000,$E37)=0,0,L37/SUMIFS($L$3:$L$20000,$D$3:$D$20000,$D37,$E$3:$E$20000,$E37)) -> 0.00046673049 | P37: 1316389 | Q37: =P37/1000 -> 1316.389 | R37: 12483 | S37: =R37/1000 -> 12.483 | T37: =IF(SUMIFS($P$3:$P$20000,$D$3:$D$20000,$D37,$E$3:$E$20000,$E37)=0,0,P37/SUMIFS($P$3:$P$20000,$D$3:$D$20000,$D37,$E$3:$E$20000,$E37)) -> 0.050718819 | U37: =IF(SUMIFS($R$3:$R$20000,$D$3:$D$20000,$D37,$E$3:$E$20000,$E37)=0,0,R37/SUMIFS($R$3:$R$20000,$D$3:$D$20000,$D37,$E$3:$E$20000,$E37)) -> 0.063044499 | V37: 91177537 | W37: 167120 | X37: 25954646 | Y37: 198003 | Z37: 10 | AA37: Ta|2021|W|10
A38: Ta|2021|11 | B38: MNRL0026 | C38: 탄탈륨 | D38: Ta | E38: 2021 | F38: 11 | G38: GB | H38: 영국 | I38: United Kingdom | J38: 25239 | K38: =J38/1000 -> 25.239 | L38: 50 | M38: =L38/1000 -> 0.05 | N38: =IF(SUMIFS($J$3:$J$20000,$D$3:$D$20000,$D38,$E$3:$E$20000,$E38)=0,0,J38/SUMIFS($J$3:$J$20000,$D$3:$D$20000,$D38,$E$3:$E$20000,$E38)) -> 0.0002768116 | O38: =IF(SUMIFS($L$3:$L$20000,$D$3:$D$20000,$D38,$E$3:$E$20000,$E38)=0,0,L38/SUMIFS($L$3:$L$20000,$D$3:$D$20000,$D38,$E$3:$E$20000,$E38)) -> 0.00029918621 | P38: 0 | Q38: =P38/1000 -> 0 | R38: 0 | S38: =R38/1000 -> 0 | T38: =IF(SUMIFS($P$3:$P$20000,$D$3:$D$20000,$D38,$E$3:$E$20000,$E38)=0,0,P38/SUMIFS($P$3:$P$20000,$D$3:$D$20000,$D38,$E$3:$E$20000,$E38)) -> 0 | U38: =IF(SUMIFS($R$3:$R$20000,$D$3:$D$20000,$D38,$E$3:$E$20000,$E38)=0,0,R38/SUMIFS($R$3:$R$20000,$D$3:$D$20000,$D38,$E$3:$E$20000,$E38)) -> 0 | V38: 91177537 | W38: 167120 | X38: 25954646 | Y38: 198003 | Z38: 11 | AA38: Ta|2021|W|11
A39: Ta|2021|12 | B39: MNRL0026 | C39: 탄탈륨 | D39: Ta | E39: 2021 | F39: 12 | G39: FI | H39: 핀란드 | J39: 21893 | K39: =J39/1000 -> 21.893 | L39: 145 | M39: =L39/1000 -> 0.145 | N39: =IF(SUMIFS($J$3:$J$20000,$D$3:$D$20000,$D39,$E$3:$E$20000,$E39)=0,0,J39/SUMIFS($J$3:$J$20000,$D$3:$D$20000,$D39,$E$3:$E$20000,$E39)) -> 0.00024011397 | O39: =IF(SUMIFS($L$3:$L$20000,$D$3:$D$20000,$D39,$E$3:$E$20000,$E39)=0,0,L39/SUMIFS($L$3:$L$20000,$D$3:$D$20000,$D39,$E$3:$E$20000,$E39)) -> 0.00086764002 | P39: 0 | Q39: =P39/1000 -> 0 | R39: 0 | S39: =R39/1000 -> 0 | T39: =IF(SUMIFS($P$3:$P$20000,$D$3:$D$20000,$D39,$E$3:$E$20000,$E39)=0,0,P39/SUMIFS($P$3:$P$20000,$D$3:$D$20000,$D39,$E$3:$E$20000,$E39)) -> 0 | U39: =IF(SUMIFS($R$3:$R$20000,$D$3:$D$20000,$D39,$E$3:$E$20000,$E39)=0,0,R39/SUMIFS($R$3:$R$20000,$D$3:$D$20000,$D39,$E$3:$E$20000,$E39)) -> 0 | V39: 91177537 | W39: 167120 | X39: 25954646 | Y39: 198003 | Z39: 9 | AA39: Ta|2021|W|9
A40: Ta|2021|13 | B40: MNRL0026 | C40: 탄탈륨 | D40: Ta | E40: 2021 | F40: 13 | G40: DK | H40: 덴마크 | I40: Denmark | J40: 20358 | K40: =J40/1000 -> 20.358 | L40: 25 | M40: =L40/1000 -> 0.025 | N40: =IF(SUMIFS($J$3:$J$20000,$D$3:$D$20000,$D40,$E$3:$E$20000,$E40)=0,0,J40/SUMIFS($J$3:$J$20000,$D$3:$D$20000,$D40,$E$3:$E$20000,$E40)) -> 0.00022327868 | O40: =IF(SUMIFS($L$3:$L$20000,$D$3:$D$20000,$D40,$E$3:$E$20000,$E40)=0,0,L40/SUMIFS($L$3:$L$20000,$D$3:$D$20000,$D40,$E$3:$E$20000,$E40)) -> 0.00014959311 | P40: 4746 | Q40: =P40/1000 -> 4.746 | R40: 0 | S40: =R40/1000 -> 0 | T40: =IF(SUMIFS($P$3:$P$20000,$D$3:$D$20000,$D40,$E$3:$E$20000,$E40)=0,0,P40/SUMIFS($P$3:$P$20000,$D$3:$D$20000,$D40,$E$3:$E$20000,$E40)) -> 0.00018285744 | U40: =IF(SUMIFS($R$3:$R$20000,$D$3:$D$20000,$D40,$E$3:$E$20000,$E40)=0,0,R40/SUMIFS($R$3:$R$20000,$D$3:$D$20000,$D40,$E$3:$E$20000,$E40)) -> 0 | V40: 91177537 | W40: 167120 | X40: 25954646 | Y40: 198003 | Z40: 14 | AA40: Ta|2021|W|14
A41: Ta|2021|14 | B41: MNRL0026 | C41: 탄탈륨 | D41: Ta | E41: 2021 | F41: 14 | G41: LI | H41: 리히텐슈타인 | J41: 9214 | K41: =J41/1000 -> 9.214 | L41: 2 | M41: =L41/1000 -> 0.002 | N41: =IF(SUMIFS($J$3:$J$20000,$D$3:$D$20000,$D41,$E$3:$E$20000,$E41)=0,0,J41/SUMIFS($J$3:$J$20000,$D$3:$D$20000,$D41,$E$3:$E$20000,$E41)) -> 0.00010105559 | O41: =IF(SUMIFS($L$3:$L$20000,$D$3:$D$20000,$D41,$E$3:$E$20000,$E41)=0,0,L41/SUMIFS($L$3:$L$20000,$D$3:$D$20000,$D41,$E$3:$E$20000,$E41)) -> 1.1967449e-05 | P41: 0 | Q41: =P41/1000 -> 0 | R41: 0 | S41: =R41/1000 -> 0 | T41: =IF(SUMIFS($P$3:$P$20000,$D$3:$D$20000,$D41,$E$3:$E$20000,$E41)=0,0,P41/SUMIFS($P$3:$P$20000,$D$3:$D$20000,$D41,$E$3:$E$20000,$E41)) -> 0 | U41: =IF(SUMIFS($R$3:$R$20000,$D$3:$D$20000,$D41,$E$3:$E$20000,$E41)=0,0,R41/SUMIFS($R$3:$R$20000,$D$3:$D$20000,$D41,$E$3:$E$20000,$E41)) -> 0 | V41: 91177537 | W41: 167120 | X41: 25954646 | Y41: 198003 | Z41: 16 | AA41: Ta|2021|W|16
...

Sheet 요약
A1: 관세청(KOMIS 대한민국 광물지도) 기준. 모든 수치는 '관세청_연도별_국가' 시트에서 수식으로 집계. 비중=해당국 수입금액/총수입금액. 2026년은 1~9월 누계(전년비는 연간 대비이므로 참고용).
A2: 광종 | B2: 원소 | C2: 연도 | D2: 수입금액(천USD) | E2: 수입중량(톤) | F2: 수입금액 전년비 | G2: 수입중량 전년비 | H2: 수출금액(천USD) | I2: 수출중량(톤) | J2: 수입국 수 | K2: 1위 수입국 | L2: 1위 비중(금액) | M2: 2위 수입국 | N2: 2위 비중(금액) | O2: 3위 수입국 | P2: 3위 비중(금액) | Q2: 주요 수입국 Top3 (금액비중) | R2: 1위 수입국(중량기준) | S2: 1위 비중(중량) | T2: 비고
A3: 탄탈륨 | B3: Ta | C3: 2020 | D3: =SUMIFS(관세청_연도별_국가!$J:$J,관세청_연도별_국가!$D:$D,$B3,관세청_연도별_국가!$E:$E,$C3)/1000 -> 72834.26 | E3: =SUMIFS(관세청_연도별_국가!$L:$L,관세청_연도별_국가!$D:$D,$B3,관세청_연도별_국가!$E:$E,$C3)/1000 -> 132.417 | H3: =SUMIFS(관세청_연도별_국가!$P:$P,관세청_연도별_국가!$D:$D,$B3,관세청_연도별_국가!$E:$E,$C3)/1000 -> 17941.594 | I3: =SUMIFS(관세청_연도별_국가!$R:$R,관세청_연도별_국가!$D:$D,$B3,관세청_연도별_국가!$E:$E,$C3)/1000 -> 153.442 | J3: =COUNTIFS(관세청_연도별_국가!$D:$D,$B3,관세청_연도별_국가!$E:$E,$C3,관세청_연도별_국가!$J:$J,">0") -> 20 | K3: =IFERROR(INDEX(관세청_연도별_국가!$H:$H,MATCH($B3&"|"&$C3&"|1",관세청_연도별_국가!$A:$A,0)),"") -> 미국 | L3: =IFERROR(INDEX(관세청_연도별_국가!$N:$N,MATCH($B3&"|"&$C3&"|1",관세청_연도별_국가!$A:$A,0)),"") -> 0.52239586 | M3: =IFERROR(INDEX(관세청_연도별_국가!$H:$H,MATCH($B3&"|"&$C3&"|2",관세청_연도별_국가!$A:$A,0)),"") -> 일본 | N3: =IFERROR(INDEX(관세청_연도별_국가!$N:$N,MATCH($B3&"|"&$C3&"|2",관세청_연도별_국가!$A:$A,0)),"") -> 0.27692127 | O3: =IFERROR(INDEX(관세청_연도별_국가!$H:$H,MATCH($B3&"|"&$C3&"|3",관세청_연도별_국가!$A:$A,0)),"") -> 중국 | P3: =IFERROR(INDEX(관세청_연도별_국가!$N:$N,MATCH($B3&"|"&$C3&"|3",관세청_연도별_국가!$A:$A,0)),"") -> 0.18885135 | Q3: =IF(K3="","",K3&" ("&TEXT(L3,"0.0%")&")")&IF(M3="","",", "&M3&" ("&TEXT(N3,"0.0%")&")")&IF(O3="","",", "&O3&" ("&TEXT(P3,"0.0%")&")") -> 미국 (52.2%), 일본 (27.7%), 중국 (18.9%) | R3: =IFERROR(INDEX(관세청_연도별_국가!$H:$H,MATCH($B3&"|"&$C3&"|W|1",관세청_연도별_국가!$AA:$AA,0)),"") -> 미국 | S3: =IFERROR(INDEX(관세청_연도별_국가!$O:$O,MATCH($B3&"|"&$C3&"|W|1",관세청_연도별_국가!$AA:$AA,0)),"") -> 0.40707009
A4: 탄탈륨 | B4: Ta | C4: 2021 | D4: =SUMIFS(관세청_연도별_국가!$J:$J,관세청_연도별_국가!$D:$D,$B4,관세청_연도별_국가!$E:$E,$C4)/1000 -> 91177.537 | E4: =SUMIFS(관세청_연도별_국가!$L:$L,관세청_연도별_국가!$D:$D,$B4,관세청_연도별_국가!$E:$E,$C4)/1000 -> 167.12 | F4: =IF(D3=0,"",D4/D3-1) -> 0.25184957 | G4: =IF(E3=0,"",E4/E3-1) -> 0.2620736 | H4: =SUMIFS(관세청_연도별_국가!$P:$P,관세청_연도별_국가!$D:$D,$B4,관세청_연도별_국가!$E:$E,$C4)/1000 -> 25954.646 | I4: =SUMIFS(관세청_연도별_국가!$R:$R,관세청_연도별_국가!$D:$D,$B4,관세청_연도별_국가!$E:$E,$C4)/1000 -> 198.003 | J4: =COUNTIFS(관세청_연도별_국가!$D:$D,$B4,관세청_연도별_국가!$E:$E,$C4,관세청_연도별_국가!$J:$J,">0") -> 22 | K4: =IFERROR(INDEX(관세청_연도별_국가!$H:$H,MATCH($B4&"|"&$C4&"|1",관세청_연도별_국가!$A:$A,0)),"") -> 미국 | L4: =IFERROR(INDEX(관세청_연도별_국가!$N:$N,MATCH($B4&"|"&$C4&"|1",관세청_연도별_국가!$A:$A,0)),"") -> 0.5809872 | M4: =IFERROR(INDEX(관세청_연도별_국가!$H:$H,MATCH($B4&"|"&$C4&"|2",관세청_연도별_국가!$A:$A,0)),"") -> 일본 | N4: =IFERROR(INDEX(관세청_연도별_국가!$N:$N,MATCH($B4&"|"&$C4&"|2",관세청_연도별_국가!$A:$A,0)),"") -> 0.26608725 | O4: =IFERROR(INDEX(관세청_연도별_국가!$H:$H,MATCH($B4&"|"&$C4&"|3",관세청_연도별_국가!$A:$A,0)),"") -> 중국 | P4: =IFERROR(INDEX(관세청_연도별_국가!$N:$N,MATCH($B4&"|"&$C4&"|3",관세청_연도별_국가!$A:$A,0)),"") -> 0.14304806 | Q4: =IF(K4="","",K4&" ("&TEXT(L4,"0.0%")&")")&IF(M4="","",", "&M4&" ("&TEXT(N4,"0.0%")&")")&IF(O4="","",", "&O4&" ("&TEXT(P4,"0.0%")&")") -> 미국 (58.1%), 일본 (26.6%), 중국 (14.3%) | R4: =IFERROR(INDEX(관세청_연도별_국가!$H:$H,MATCH($B4&"|"&$C4&"|W|1",관세청_연도별_국가!$AA:$AA,0)),"") -> 미국 | S4: =IFERROR(INDEX(관세청_연도별_국가!$O:$O,MATCH($B4&"|"&$C4&"|W|1",관세청_연도별_국가!$AA:$AA,0)),"") -> 0.44971876
A5: 탄탈륨 | B5: Ta | C5: 2022 | D5: =SUMIFS(관세청_연도별_국가!$J:$J,관세청_연도별_국가!$D:$D,$B5,관세청_연도별_국가!$E:$E,$C5)/1000 -> 111814.01 | E5: =SUMIFS(관세청_연도별_국가!$L:$L,관세청_연도별_국가!$D:$D,$B5,관세청_연도별_국가!$E:$E,$C5)/1000 -> 208.65 | F5: =IF(D4=0,"",D5/D4-1) -> 0.2263329 | G5: =IF(E4=0,"",E5/E4-1) -> 0.24850407 | H5: =SUMIFS(관세청_연도별_국가!$P:$P,관세청_연도별_국가!$D:$D,$B5,관세청_연도별_국가!$E:$E,$C5)/1000 -> 29675.121 | I5: =SUMIFS(관세청_연도별_국가!$R:$R,관세청_연도별_국가!$D:$D,$B5,관세청_연도별_국가!$E:$E,$C5)/1000 -> 154.406 | J5: =COUNTIFS(관세청_연도별_국가!$D:$D,$B5,관세청_연도별_국가!$E:$E,$C5,관세청_연도별_국가!$J:$J,">0") -> 18 | K5: =IFERROR(INDEX(관세청_연도별_국가!$H:$H,MATCH($B5&"|"&$C5&"|1",관세청_연도별_국가!$A:$A,0)),"") -> 미국 | L5: =IFERROR(INDEX(관세청_연도별_국가!$N:$N,MATCH($B5&"|"&$C5&"|1",관세청_연도별_국가!$A:$A,0)),"") -> 0.51676199 | M5: =IFERROR(INDEX(관세청_연도별_국가!$H:$H,MATCH($B5&"|"&$C5&"|2",관세청_연도별_국가!$A:$A,0)),"") -> 일본 | N5: =IFERROR(INDEX(관세청_연도별_국가!$N:$N,MATCH($B5&"|"&$C5&"|2",관세청_연도별_국가!$A:$A,0)),"") -> 0.25284416 | O5: =IFERROR(INDEX(관세청_연도별_국가!$H:$H,MATCH($B5&"|"&$C5&"|3",관세청_연도별_국가!$A:$A,0)),"") -> 중국 | P5: =IFERROR(INDEX(관세청_연도별_국가!$N:$N,MATCH($B5&"|"&$C5&"|3",관세청_연도별_국가!$A:$A,0)),"") -> 0.19759013 | Q5: =IF(K5="","",K5&" ("&TEXT(L5,"0.0%")&")")&IF(M5="","",", "&M5&" ("&TEXT(N5,"0.0%")&")")&IF(O5="","",", "&O5&" ("&TEXT(P5,"0.0%")&")") -> 미국 (51.7%), 일본 (25.3%), 중국 (19.8%) | R5: =IFERROR(INDEX(관세청_연도별_국가!$H:$H,MATCH($B5&"|"&$C5&"|W|1",관세청_연도별_국가!$AA:$AA,0)),"") -> 미국 | S5: =IFERROR(INDEX(관세청_연도별_국가!$O:$O,MATCH($B5&"|"&$C5&"|W|1",관세청_연도별_국가!$AA:$AA,0)),"") -> 0.37491493
A6: 탄탈륨 | B6: Ta | C6: 2023 | D6: =SUMIFS(관세청_연도별_국가!$J:$J,관세청_연도별_국가!$D:$D,$B6,관세청_연도별_국가!$E:$E,$C6)/1000 -> 104043.04 | E6: =SUMIFS(관세청_연도별_국가!$L:$L,관세청_연도별_국가!$D:$D,$B6,관세청_연도별_국가!$E:$E,$C6)/1000 -> 191.866 | F6: =IF(D5=0,"",D6/D5-1) -> -0.069499133 | G6: =IF(E5=0,"",E6/E5-1) -> -0.08044093 | H6: =SUMIFS(관세청_연도별_국가!$P:$P,관세청_연도별_국가!$D:$D,$B6,관세청_연도별_국가!$E:$E,$C6)/1000 -> 23636.832 | I6: =SUMIFS(관세청_연도별_국가!$R:$R,관세청_연도별_국가!$D:$D,$B6,관세청_연도별_국가!$E:$E,$C6)/1000 -> 176.646 | J6: =COUNTIFS(관세청_연도별_국가!$D:$D,$B6,관세청_연도별_국가!$E:$E,$C6,관세청_연도별_국가!$J:$J,">0") -> 20 | K6: =IFERROR(INDEX(관세청_연도별_국가!$H:$H,MATCH($B6&"|"&$C6&"|1",관세청_연도별_국가!$A:$A,0)),"") -> 미국 | L6: =IFERROR(INDEX(관세청_연도별_국가!$N:$N,MATCH($B6&"|"&$C6&"|1",관세청_연도별_국가!$A:$A,0)),"") -> 0.46031441 | M6: =IFERROR(INDEX(관세청_연도별_국가!$H:$H,MATCH($B6&"|"&$C6&"|2",관세청_연도별_국가!$A:$A,0)),"") -> 일본 | N6: =IFERROR(INDEX(관세청_연도별_국가!$N:$N,MATCH($B6&"|"&$C6&"|2",관세청_연도별_국가!$A:$A,0)),"") -> 0.26648818 | O6: =IFERROR(INDEX(관세청_연도별_국가!$H:$H,MATCH($B6&"|"&$C6&"|3",관세청_연도별_국가!$A:$A,0)),"") -> 중국 | P6: =IFERROR(INDEX(관세청_연도별_국가!$N:$N,MATCH($B6&"|"&$C6&"|3",관세청_연도별_국가!$A:$A,0)),"") -> 0.25450781 | Q6: =IF(K6="","",K6&" ("&TEXT(L6,"0.0%")&")")&IF(M6="","",", "&M6&" ("&TEXT(N6,"0.0%")&")")&IF(O6="","",", "&O6&" ("&TEXT(P6,"0.0%")&")") -> 미국 (46.0%), 일본 (26.6%), 중국 (25.5%) | R6: =IFERROR(INDEX(관세청_연도별_국가!$H:$H,MATCH($B6&"|"&$C6&"|W|1",관세청_연도별_국가!$AA:$AA,0)),"") -> 일본 | S6: =IFERROR(INDEX(관세청_연도별_국가!$O:$O,MATCH($B6&"|"&$C6&"|W|1",관세청_연도별_국가!$AA:$AA,0)),"") -> 0.3212294
A7: 탄탈륨 | B7: Ta | C7: 2024 | D7: =SUMIFS(관세청_연도별_국가!$J:$J,관세청_연도별_국가!$D:$D,$B7,관세청_연도별_국가!$E:$E,$C7)/1000 -> 134452.2 | E7: =SUMIFS(관세청_연도별_국가!$L:$L,관세청_연도별_국가!$D:$D,$B7,관세청_연도별_국가!$E:$E,$C7)/1000 -> 290.241 | F7: =IF(D6=0,"",D7/D6-1) -> 0.29227487 | G7: =IF(E6=0,"",E7/E6-1) -> 0.51272763 | H7: =SUMIFS(관세청_연도별_국가!$P:$P,관세청_연도별_국가!$D:$D,$B7,관세청_연도별_국가!$E:$E,$C7)/1000 -> 38618.293 | I7: =SUMIFS(관세청_연도별_국가!$R:$R,관세청_연도별_국가!$D:$D,$B7,관세청_연도별_국가!$E:$E,$C7)/1000 -> 230.705 | J7: =COUNTIFS(관세청_연도별_국가!$D:$D,$B7,관세청_연도별_국가!$E:$E,$C7,관세청_연도별_국가!$J:$J,">0") -> 16 | K7: =IFERROR(INDEX(관세청_연도별_국가!$H:$H,MATCH($B7&"|"&$C7&"|1",관세청_연도별_국가!$A:$A,0)),"") -> 미국 | L7: =IFERROR(INDEX(관세청_연도별_국가!$N:$N,MATCH($B7&"|"&$C7&"|1",관세청_연도별_국가!$A:$A,0)),"") -> 0.41462354 | M7: =IFERROR(INDEX(관세청_연도별_국가!$H:$H,MATCH($B7&"|"&$C7&"|2",관세청_연도별_국가!$A:$A,0)),"") -> 중국 | N7: =IFERROR(INDEX(관세청_연도별_국가!$N:$N,MATCH($B7&"|"&$C7&"|2",관세청_연도별_국가!$A:$A,0)),"") -> 0.28357284 | O7: =IFERROR(INDEX(관세청_연도별_국가!$H:$H,MATCH($B7&"|"&$C7&"|3",관세청_연도별_국가!$A:$A,0)),"") -> 일본 | P7: =IFERROR(INDEX(관세청_연도별_국가!$N:$N,MATCH($B7&"|"&$C7&"|3",관세청_연도별_국가!$A:$A,0)),"") -> 0.27077776 | Q7: =IF(K7="","",K7&" ("&TEXT(L7,"0.0%")&")")&IF(M7="","",", "&M7&" ("&TEXT(N7,"0.0%")&")")&IF(O7="","",", "&O7&" ("&TEXT(P7,"0.0%")&")") -> 미국 (41.5%), 중국 (28.4%), 일본 (27.1%) | R7: =IFERROR(INDEX(관세청_연도별_국가!$H:$H,MATCH($B7&"|"&$C7&"|W|1",관세청_연도별_국가!$AA:$AA,0)),"") -> 일본 | S7: =IFERROR(INDEX(관세청_연도별_국가!$O:$O,MATCH($B7&"|"&$C7&"|W|1",관세청_연도별_국가!$AA:$AA,0)),"") -> 0.32741067
A8: 탄탈륨 | B8: Ta | C8: 2025 | D8: =SUMIFS(관세청_연도별_국가!$J:$J,관세청_연도별_국가!$D:$D,$B8,관세청_연도별_국가!$E:$E,$C8)/1000 -> 118438.01 | E8: =SUMIFS(관세청_연도별_국가!$L:$L,관세청_연도별_국가!$D:$D,$B8,관세청_연도별_국가!$E:$E,$C8)/1000 -> 270.143 | F8: =IF(D7=0,"",D8/D7-1) -> -0.11910691 | G8: =IF(E7=0,"",E8/E7-1) -> -0.069245903 | H8: =SUMIFS(관세청_연도별_국가!$P:$P,관세청_연도별_국가!$D:$D,$B8,관세청_연도별_국가!$E:$E,$C8)/1000 -> 27876.494 | I8: =SUMIFS(관세청_연도별_국가!$R:$R,관세청_연도별_국가!$D:$D,$B8,관세청_연도별_국가!$E:$E,$C8)/1000 -> 225.946 | J8: =COUNTIFS(관세청_연도별_국가!$D:$D,$B8,관세청_연도별_국가!$E:$E,$C8,관세청_연도별_국가!$J:$J,">0") -> 18 | K8: =IFERROR(INDEX(관세청_연도별_국가!$H:$H,MATCH($B8&"|"&$C8&"|1",관세청_연도별_국가!$A:$A,0)),"") -> 미국 | L8: =IFERROR(INDEX(관세청_연도별_국가!$N:$N,MATCH($B8&"|"&$C8&"|1",관세청_연도별_국가!$A:$A,0)),"") -> 0.45221979 | M8: =IFERROR(INDEX(관세청_연도별_국가!$H:$H,MATCH($B8&"|"&$C8&"|2",관세청_연도별_국가!$A:$A,0)),"") -> 일본 | N8: =IFERROR(INDEX(관세청_연도별_국가!$N:$N,MATCH($B8&"|"&$C8&"|2",관세청_연도별_국가!$A:$A,0)),"") -> 0.33054406 | O8: =IFERROR(INDEX(관세청_연도별_국가!$H:$H,MATCH($B8&"|"&$C8&"|3",관세청_연도별_국가!$A:$A,0)),"") -> 중국 | P8: =IFERROR(INDEX(관세청_연도별_국가!$N:$N,MATCH($B8&"|"&$C8&"|3",관세청_연도별_국가!$A:$A,0)),"") -> 0.20605813 | Q8: =IF(K8="","",K8&" ("&TEXT(L8,"0.0%")&")")&IF(M8="","",", "&M8&" ("&TEXT(N8,"0.0%")&")")&IF(O8="","",", "&O8&" ("&TEXT(P8,"0.0%")&")") -> 미국 (45.2%), 일본 (33.1%), 중국 (20.6%) | R8: =IFERROR(INDEX(관세청_연도별_국가!$H:$H,MATCH($B8&"|"&$C8&"|W|1",관세청_연도별_국가!$AA:$AA,0)),"") -> 일본 | S8: =IFERROR(INDEX(관세청_연도별_국가!$O:$O,MATCH($B8&"|"&$C8&"|W|1",관세청_연도별_국가!$AA:$AA,0)),"") -> 0.42997968
A9: 탄탈륨 | B9: Ta | C9: 2026 | D9: =SUMIFS(관세청_연도별_국가!$J:$J,관세청_연도별_국가!$D:$D,$B9,관세청_연도별_국가!$E:$E,$C9)/1000 -> 64529.864 | E9: =SUMIFS(관세청_연도별_국가!$L:$L,관세청_연도별_국가!$D:$D,$B9,관세청_연도별_국가!$E:$E,$C9)/1000 -> 81.128 | F9: =IF(D8=0,"",D9/D8-1) -> -0.45515919 | G9: =IF(E8=0,"",E9/E8-1) -> -0.69968498 | H9: =SUMIFS(관세청_연도별_국가!$P:$P,관세청_연도별_국가!$D:$D,$B9,관세청_연도별_국가!$E:$E,$C9)/1000 -> 29318.588 | I9: =SUMIFS(관세청_연도별_국가!$R:$R,관세청_연도별_국가!$D:$D,$B9,관세청_연도별_국가!$E:$E,$C9)/1000 -> 223.594 | J9: =COUNTIFS(관세청_연도별_국가!$D:$D,$B9,관세청_연도별_국가!$E:$E,$C9,관세청_연도별_국가!$J:$J,">0") -> 18 | K9: =IFERROR(INDEX(관세청_연도별_국가!$H:$H,MATCH($B9&"|"&$C9&"|1",관세청_연도별_국가!$A:$A,0)),"") -> 미국 | L9: =IFERROR(INDEX(관세청_연도별_국가!$N:$N,MATCH($B9&"|"&$C9&"|1",관세청_연도별_국가!$A:$A,0)),"") -> 0.79639091 | M9: =IFERROR(INDEX(관세청_연도별_국가!$H:$H,MATCH($B9&"|"&$C9&"|2",관세청_연도별_국가!$A:$A,0)),"") -> 중국 | N9: =IFERROR(INDEX(관세청_연도별_국가!$N:$N,MATCH($B9&"|"&$C9&"|2",관세청_연도별_국가!$A:$A,0)),"") -> 0.16233947 | O9: =IFERROR(INDEX(관세청_연도별_국가!$H:$H,MATCH($B9&"|"&$C9&"|3",관세청_연도별_국가!$A:$A,0)),"") -> 필리핀 | P9: =IFERROR(INDEX(관세청_연도별_국가!$N:$N,MATCH($B9&"|"&$C9&"|3",관세청_연도별_국가!$A:$A,0)),"") -> 0.0128909 | Q9: =IF(K9="","",K9&" ("&TEXT(L9,"0.0%")&")")&IF(M9="","",", "&M9&" ("&TEXT(N9,"0.0%")&")")&IF(O9="","",", "&O9&" ("&TEXT(P9,"0.0%")&")") -> 미국 (79.6%), 중국 (16.2%), 필리핀 (1.3%) | R9: =IFERROR(INDEX(관세청_연도별_국가!$H:$H,MATCH($B9&"|"&$C9&"|W|1",관세청_연도별_국가!$AA:$AA,0)),"") -> 미국 | S9: =IFERROR(INDEX(관세청_연도별_국가!$O:$O,MATCH($B9&"|"&$C9&"|W|1",관세청_연도별_국가!$AA:$AA,0)),"") -> 0.72968642 | T9: 2026년은 1~9월 누계
A10: 니오븀 | B10: Nb | C10: 2020 | D10: =SUMIFS(관세청_연도별_국가!$J:$J,관세청_연도별_국가!$D:$D,$B10,관세청_연도별_국가!$E:$E,$C10)/1000 -> 153511.49 | E10: =SUMIFS(관세청_연도별_국가!$L:$L,관세청_연도별_국가!$D:$D,$B10,관세청_연도별_국가!$E:$E,$C10)/1000 -> 6262.966 | H10: =SUMIFS(관세청_연도별_국가!$P:$P,관세청_연도별_국가!$D:$D,$B10,관세청_연도별_국가!$E:$E,$C10)/1000 -> 2359.506 | I10: =SUMIFS(관세청_연도별_국가!$R:$R,관세청_연도별_국가!$D:$D,$B10,관세청_연도별_국가!$E:$E,$C10)/1000 -> 74.781 | J10: =COUNTIFS(관세청_연도별_국가!$D:$D,$B10,관세청_연도별_국가!$E:$E,$C10,관세청_연도별_국가!$J:$J,">0") -> 12 | K10: =IFERROR(INDEX(관세청_연도별_국가!$H:$H,MATCH($B10&"|"&$C10&"|1",관세청_연도별_국가!$A:$A,0)),"") -> 브라질 | L10: =IFERROR(INDEX(관세청_연도별_국가!$N:$N,MATCH($B10&"|"&$C10&"|1",관세청_연도별_국가!$A:$A,0)),"") -> 0.90011933 | M10: =IFERROR(INDEX(관세청_연도별_국가!$H:$H,MATCH($B10&"|"&$C10&"|2",관세청_연도별_국가!$A:$A,0)),"") -> 캐나다 | N10: =IFERROR(INDEX(관세청_연도별_국가!$N:$N,MATCH($B10&"|"&$C10&"|2",관세청_연도별_국가!$A:$A,0)),"") -> 0.047432566 | O10: =IFERROR(INDEX(관세청_연도별_국가!$H:$H,MATCH($B10&"|"&$C10&"|3",관세청_연도별_국가!$A:$A,0)),"") -> 미국 | P10: =IFERROR(INDEX(관세청_연도별_국가!$N:$N,MATCH($B10&"|"&$C10&"|3",관세청_연도별_국가!$A:$A,0)),"") -> 0.034828526 | Q10: =IF(K10="","",K10&" ("&TEXT(L10,"0.0%")&")")&IF(M10="","",", "&M10&" ("&TEXT(N10,"0.0%")&")")&IF(O10="","",", "&O10&" ("&TEXT(P10,"0.0%")&")") -> 브라질 (90.0%), 캐나다 (4.7%), 미국 (3.5%) | R10: =IFERROR(INDEX(관세청_연도별_국가!$H:$H,MATCH($B10&"|"&$C10&"|W|1",관세청_연도별_국가!$AA:$AA,0)),"") -> 브라질 | S10: =IFERROR(INDEX(관세청_연도별_국가!$O:$O,MATCH($B10&"|"&$C10&"|W|1",관세청_연도별_국가!$AA:$AA,0)),"") -> 0.94172633
A11: 니오븀 | B11: Nb | C11: 2021 | D11: =SUMIFS(관세청_연도별_국가!$J:$J,관세청_연도별_국가!$D:$D,$B11,관세청_연도별_국가!$E:$E,$C11)/1000 -> 200215.97 | E11: =SUMIFS(관세청_연도별_국가!$L:$L,관세청_연도별_국가!$D:$D,$B11,관세청_연도별_국가!$E:$E,$C11)/1000 -> 7939.319 | F11: =IF(D10=0,"",D11/D10-1) -> 0.30424089 | G11: =IF(E10=0,"",E11/E10-1) -> 0.2676612 | H11: =SUMIFS(관세청_연도별_국가!$P:$P,관세청_연도별_국가!$D:$D,$B11,관세청_연도별_국가!$E:$E,$C11)/1000 -> 4616.073 | I11: =SUMIFS(관세청_연도별_국가!$R:$R,관세청_연도별_국가!$D:$D,$B11,관세청_연도별_국가!$E:$E,$C11)/1000 -> 162.993 | J11: =COUNTIFS(관세청_연도별_국가!$D:$D,$B11,관세청_연도별_국가!$E:$E,$C11,관세청_연도별_국가!$J:$J,">0") -> 12 | K11: =IFERROR(INDEX(관세청_연도별_국가!$H:$H,MATCH($B11&"|"&$C11&"|1",관세청_연도별_국가!$A:$A,0)),"") -> 브라질 | L11: =IFERROR(INDEX(관세청_연도별_국가!$N:$N,MATCH($B11&"|"&$C11&"|1",관세청_연도별_국가!$A:$A,0)),"") -> 0.96672477 | M11: =IFERROR(INDEX(관세청_연도별_국가!$H:$H,MATCH($B11&"|"&$C11&"|2",관세청_연도별_국가!$A:$A,0)),"") -> 캐나다 | N11: =IFERROR(INDEX(관세청_연도별_국가!$N:$N,MATCH($B11&"|"&$C11&"|2",관세청_연도별_국가!$A:$A,0)),"") -> 0.012346788 | O11: =IFERROR(INDEX(관세청_연도별_국가!$H:$H,MATCH($B11&"|"&$C11&"|3",관세청_연도별_국가!$A:$A,0)),"") -> 미국 | P11: =IFERROR(INDEX(관세청_연도별_국가!$N:$N,MATCH($B11&"|"&$C11&"|3",관세청_연도별_국가!$A:$A,0)),"") -> 0.0087996778 | Q11: =IF(K11="","",K11&" ("&TEXT(L11,"0.0%")&")")&IF(M11="","",", "&M11&" ("&TEXT(N11,"0.0%")&")")&IF(O11="","",", "&O11&" ("&TEXT(P11,"0.0%")&")") -> 브라질 (96.7%), 캐나다 (1.2%), 미국 (0.9%) | R11: =IFERROR(INDEX(관세청_연도별_국가!$H:$H,MATCH($B11&"|"&$C11&"|W|1",관세청_연도별_국가!$AA:$AA,0)),"") -> 브라질 | S11: =IFERROR(INDEX(관세청_연도별_국가!$O:$O,MATCH($B11&"|"&$C11&"|W|1",관세청_연도별_국가!$AA:$AA,0)),"") -> 0.98182224
A12: 니오븀 | B12: Nb | C12: 2022 | D12: =SUMIFS(관세청_연도별_국가!$J:$J,관세청_연도별_국가!$D:$D,$B12,관세청_연도별_국가!$E:$E,$C12)/1000 -> 195498.99 | E12: =SUMIFS(관세청_연도별_국가!$L:$L,관세청_연도별_국가!$D:$D,$B12,관세청_연도별_국가!$E:$E,$C12)/1000 -> 6940.047 | F12: =IF(D11=0,"",D12/D11-1) -> -0.023559465 | G12: =IF(E11=0,"",E12/E11-1) -> -0.12586369 | H12: =SUMIFS(관세청_연도별_국가!$P:$P,관세청_연도별_국가!$D:$D,$B12,관세청_연도별_국가!$E:$E,$C12)/1000 -> 1331.273 | I12: =SUMIFS(관세청_연도별_국가!$R:$R,관세청_연도별_국가!$D:$D,$B12,관세청_연도별_국가!$E:$E,$C12)/1000 -> 46.029 | J12: =COUNTIFS(관세청_연도별_국가!$D:$D,$B12,관세청_연도별_국가!$E:$E,$C12,관세청_연도별_국가!$J:$J,">0") -> 8 | K12: =IFERROR(INDEX(관세청_연도별_국가!$H:$H,MATCH($B12&"|"&$C12&"|1",관세청_연도별_국가!$A:$A,0)),"") -> 브라질 | L12: =IFERROR(INDEX(관세청_연도별_국가!$N:$N,MATCH($B12&"|"&$C12&"|1",관세청_연도별_국가!$A:$A,0)),"") -> 0.9648306 | M12: =IFERROR(INDEX(관세청_연도별_국가!$H:$H,MATCH($B12&"|"&$C12&"|2",관세청_연도별_국가!$A:$A,0)),"") -> 러시아 | N12: =IFERROR(INDEX(관세청_연도별_국가!$N:$N,MATCH($B12&"|"&$C12&"|2",관세청_연도별_국가!$A:$A,0)),"") -> 0.014116196 | O12: =IFERROR(INDEX(관세청_연도별_국가!$H:$H,MATCH($B12&"|"&$C12&"|3",관세청_연도별_국가!$A:$A,0)),"") -> 중국 | P12: =IFERROR(INDEX(관세청_연도별_국가!$N:$N,MATCH($B12&"|"&$C12&"|3",관세청_연도별_국가!$A:$A,0)),"") -> 0.0099998984 | Q12: =IF(K12="","",K12&" ("&TEXT(L12,"0.0%")&")")&IF(M12="","",", "&M12&" ("&TEXT(N12,"0.0%")&")")&IF(O12="","",", "&O12&" ("&TEXT(P12,"0.0%")&")") -> 브라질 (96.5%), 러시아 (1.4%), 중국 (1.0%) | R12: =IFERROR(INDEX(관세청_연도별_국가!$H:$H,MATCH($B12&"|"&$C12&"|W|1",관세청_연도별_국가!$AA:$AA,0)),"") -> 브라질 | S12: =IFERROR(INDEX(관세청_연도별_국가!$O:$O,MATCH($B12&"|"&$C12&"|W|1",관세청_연도별_국가!$AA:$AA,0)),"") -> 0.97982045
A13: 니오븀 | B13: Nb | C13: 2023 | D13: =SUMIFS(관세청_연도별_국가!$J:$J,관세청_연도별_국가!$D:$D,$B13,관세청_연도별_국가!$E:$E,$C13)/1000 -> 219660.56 | E13: =SUMIFS(관세청_연도별_국가!$L:$L,관세청_연도별_국가!$D:$D,$B13,관세청_연도별_국가!$E:$E,$C13)/1000 -> 7537.003 | F13: =IF(D12=0,"",D13/D12-1) -> 0.12358924 | G13: =IF(E12=0,"",E13/E12-1) -> 0.086016132 | H13: =SUMIFS(관세청_연도별_국가!$P:$P,관세청_연도별_국가!$D:$D,$B13,관세청_연도별_국가!$E:$E,$C13)/1000 -> 1838.871 | I13: =SUMIFS(관세청_연도별_국가!$R:$R,관세청_연도별_국가!$D:$D,$B13,관세청_연도별_국가!$E:$E,$C13)/1000 -> 40.373 | J13: =COUNTIFS(관세청_연도별_국가!$D:$D,$B13,관세청_연도별_국가!$E:$E,$C13,관세청_연도별_국가!$J:$J,">0") -> 13 | K13: =IFERROR(INDEX(관세청_연도별_국가!$H:$H,MATCH($B13&"|"&$C13&"|1",관세청_연도별_국가!$A:$A,0)),"") -> 브라질 | L13: =IFERROR(INDEX(관세청_연도별_국가!$N:$N,MATCH($B13&"|"&$C13&"|1",관세청_연도별_국가!$A:$A,0)),"") -> 0.96592818 | M13: =IFERROR(INDEX(관세청_연도별_국가!$H:$H,MATCH($B13&"|"&$C13&"|2",관세청_연도별_국가!$A:$A,0)),"") -> 중국 | N13: =IFERROR(INDEX(관세청_연도별_국가!$N:$N,MATCH($B13&"|"&$C13&"|2",관세청_연도별_국가!$A:$A,0)),"") -> 0.010189622 | O13: =IFERROR(INDEX(관세청_연도별_국가!$H:$H,MATCH($B13&"|"&$C13&"|3",관세청_연도별_국가!$A:$A,0)),"") -> 캐나다 | P13: =IFERROR(INDEX(관세청_연도별_국가!$N:$N,MATCH($B13&"|"&$C13&"|3",관세청_연도별_국가!$A:$A,0)),"") -> 0.0099393083 | Q13: =IF(K13="","",K13&" ("&TEXT(L13,"0.0%")&")")&IF(M13="","",", "&M13&" ("&TEXT(N13,"0.0%")&")")&IF(O13="","",", "&O13&" ("&TEXT(P13,"0.0%")&")") -> 브라질 (96.6%), 중국 (1.0%), 캐나다 (1.0%) | R13: =IFERROR(INDEX(관세청_연도별_국가!$H:$H,MATCH($B13&"|"&$C13&"|W|1",관세청_연도별_국가!$AA:$AA,0)),"") -> 브라질 | S13: =IFERROR(INDEX(관세청_연도별_국가!$O:$O,MATCH($B13&"|"&$C13&"|W|1",관세청_연도별_국가!$AA:$AA,0)),"") -> 0.98011106
A14: 니오븀 | B14: Nb | C14: 2024 | D14: =SUMIFS(관세청_연도별_국가!$J:$J,관세청_연도별_국가!$D:$D,$B14,관세청_연도별_국가!$E:$E,$C14)/1000 -> 231361.61 | E14: =SUMIFS(관세청_연도별_국가!$L:$L,관세청_연도별_국가!$D:$D,$B14,관세청_연도별_국가!$E:$E,$C14)/1000 -> 7881.64 | F14: =IF(D13=0,"",D14/D13-1) -> 0.053268803 | G14: =IF(E13=0,"",E14/E13-1) -> 0.045726 | H14: =SUMIFS(관세청_연도별_국가!$P:$P,관세청_연도별_국가!$D:$D,$B14,관세청_연도별_국가!$E:$E,$C14)/1000 -> 5665.607 | I14: =SUMIFS(관세청_연도별_국가!$R:$R,관세청_연도별_국가!$D:$D,$B14,관세청_연도별_국가!$E:$E,$C14)/1000 -> 92.255 | J14: =COUNTIFS(관세청_연도별_국가!$D:$D,$B14,관세청_연도별_국가!$E:$E,$C14,관세청_연도별_국가!$J:$J,">0") -> 9 | K14: =IFERROR(INDEX(관세청_연도별_국가!$H:$H,MATCH($B14&"|"&$C14&"|1",관세청_연도별_국가!$A:$A,0)),"") -> 브라질 | L14: =IFERROR(INDEX(관세청_연도별_국가!$N:$N,MATCH($B14&"|"&$C14&"|1",관세청_연도별_국가!$A:$A,0)),"") -> 0.9701721 | M14: =IFERROR(INDEX(관세청_연도별_국가!$H:$H,MATCH($B14&"|"&$C14&"|2",관세청_연도별_국가!$A:$A,0)),"") -> 중국 | N14: =IFERROR(INDEX(관세청_연도별_국가!$N:$N,MATCH($B14&"|"&$C14&"|2",관세청_연도별_국가!$A:$A,0)),"") -> 0.015624083 | O14: =IFERROR(INDEX(관세청_연도별_국가!$H:$H,MATCH($B14&"|"&$C14&"|3",관세청_연도별_국가!$A:$A,0)),"") -> 캐나다 | P14: =IFERROR(INDEX(관세청_연도별_국가!$N:$N,MATCH($B14&"|"&$C14&"|3",관세청_연도별_국가!$A:$A,0)),"") -> 0.0078386858 | Q14: =IF(K14="","",K14&" ("&TEXT(L14,"0.0%")&")")&IF(M14="","",", "&M14&" ("&TEXT(N14,"0.0%")&")")&IF(O14="","",", "&O14&" ("&TEXT(P14,"0.0%")&")") -> 브라질 (97.0%), 중국 (1.6%), 캐나다 (0.8%) | R14: =IFERROR(INDEX(관세청_연도별_국가!$H:$H,MATCH($B14&"|"&$C14&"|W|1",관세청_연도별_국가!$AA:$AA,0)),"") -> 브라질 | S14: =IFERROR(INDEX(관세청_연도별_국가!$O:$O,MATCH($B14&"|"&$C14&"|W|1",관세청_연도별_국가!$AA:$AA,0)),"") -> 0.98685058
A15: 니오븀 | B15: Nb | C15: 2025 | D15: =SUMIFS(관세청_연도별_국가!$J:$J,관세청_연도별_국가!$D:$D,$B15,관세청_연도별_국가!$E:$E,$C15)/1000 -> 230011.5 | E15: =SUMIFS(관세청_연도별_국가!$L:$L,관세청_연도별_국가!$D:$D,$B15,관세청_연도별_국가!$E:$E,$C15)/1000 -> 7748.315 | F15: =IF(D14=0,"",D15/D14-1) -> -0.0058355143 | G15: =IF(E14=0,"",E15/E14-1) -> -0.016915896 | H15: =SUMIFS(관세청_연도별_국가!$P:$P,관세청_연도별_국가!$D:$D,$B15,관세청_연도별_국가!$E:$E,$C15)/1000 -> 5480.645 | I15: =SUMIFS(관세청_연도별_국가!$R:$R,관세청_연도별_국가!$D:$D,$B15,관세청_연도별_국가!$E:$E,$C15)/1000 -> 162.681 | J15: =COUNTIFS(관세청_연도별_국가!$D:$D,$B15,관세청_연도별_국가!$E:$E,$C15,관세청_연도별_국가!$J:$J,">0") -> 12 | K15: =IFERROR(INDEX(관세청_연도별_국가!$H:$H,MATCH($B15&"|"&$C15&"|1",관세청_연도별_국가!$A:$A,0)),"") -> 브라질 | L15: =IFERROR(INDEX(관세청_연도별_국가!$N:$N,MATCH($B15&"|"&$C15&"|1",관세청_연도별_국가!$A:$A,0)),"") -> 0.96910054 | M15: =IFERROR(INDEX(관세청_연도별_국가!$H:$H,MATCH($B15&"|"&$C15&"|2",관세청_연도별_국가!$A:$A,0)),"") -> 중국 | N15: =IFERROR(INDEX(관세청_연도별_국가!$N:$N,MATCH($B15&"|"&$C15&"|2",관세청_연도별_국가!$A:$A,0)),"") -> 0.020982894 | O15: =IFERROR(INDEX(관세청_연도별_국가!$H:$H,MATCH($B15&"|"&$C15&"|3",관세청_연도별_국가!$A:$A,0)),"") -> 미국 | P15: =IFERROR(INDEX(관세청_연도별_국가!$N:$N,MATCH($B15&"|"&$C15&"|3",관세청_연도별_국가!$A:$A,0)),"") -> 0.0069663082 | Q15: =IF(K15="","",K15&" ("&TEXT(L15,"0.0%")&")")&IF(M15="","",", "&M15&" ("&TEXT(N15,"0.0%")&")")&IF(O15="","",", "&O15&" ("&TEXT(P15,"0.0%")&")") -> 브라질 (96.9%), 중국 (2.1%), 미국 (0.7%) | R15: =IFERROR(INDEX(관세청_연도별_국가!$H:$H,MATCH($B15&"|"&$C15&"|W|1",관세청_연도별_국가!$AA:$AA,0)),"") -> 브라질 | S15: =IFERROR(INDEX(관세청_연도별_국가!$O:$O,MATCH($B15&"|"&$C15&"|W|1",관세청_연도별_국가!$AA:$AA,0)),"") -> 0.99076367
