Workbook

Sheet 전체공시
A1: No | B1: 접수일자 | C1: 연도 | D1: 공시대상회사 | E1: 공시명(보고서명) | F1: 정정구분 | G1: 공시유형 | H1: 제출인 | I1: 최종본 | J1: 비고 | K1: 접수번호(rcpNo) | L1: DART 링크
A2: 1 | B2: 46111 | C2: 2026 | D2: 코엔텍 | E2: 사업보고서 (2025.12) | G2: 정기공시 | H2: 코엔텍 | I2: Y | K2: 20260330000925 | L2: https://dart.fss.or.kr/dsaf001/main.do?rcpNo=20260330000925
A3: 2 | B3: 45975 | C3: 2025 | D3: 코엔텍 | E3: 분기보고서 (2025.09) | G3: 정기공시 | H3: 코엔텍 | I3: Y | K3: 20251114000641 | L3: https://dart.fss.or.kr/dsaf001/main.do?rcpNo=20251114000641
A4: 3 | B4: 45882 | C4: 2025 | D4: 코엔텍 | E4: 반기보고서 (2025.06) | G4: 정기공시 | H4: 코엔텍 | I4: Y | K4: 20250813000536 | L4: https://dart.fss.or.kr/dsaf001/main.do?rcpNo=20250813000536
A5: 4 | B5: 45821 | C5: 2025 | D5: 코엔텍 | E5: [기재정정] 합병등종료보고서 (주식의포괄적교환ㆍ이전) | F5: 기재정정 | G5: 발행공시 | H5: 코엔텍 | I5: Y | K5: 20250613000412 | L5: https://dart.fss.or.kr/dsaf001/main.do?rcpNo=20250613000412
A6: 5 | B6: 45818 | C6: 2025 | D6: 코엔텍 | E6: 임원ㆍ주요주주특정증권등소유상황보고서 | G6: 지분공시 | H6: 이앤아이홀딩스 | I6: Y | K6: 20250610000089 | L6: https://dart.fss.or.kr/dsaf001/main.do?rcpNo=20250610000089
A7: 6 | B7: 45818 | C7: 2025 | D7: 코엔텍 | E7: 주식등의대량보유상황보고서(일반) | G7: 지분공시 | H7: 이앤아이홀딩스 | I7: Y | K7: 20250610000087 | L7: https://dart.fss.or.kr/dsaf001/main.do?rcpNo=20250610000087
A8: 7 | B8: 45807 | C8: 2025 | D8: 코엔텍 | E8: 합병등종료보고서 (주식의포괄적교환ㆍ이전) | G8: 발행공시 | H8: 코엔텍 | I8: N | J8: 본 보고서 제출 후 정정신고가 있으니 관련 보고서를 참조하시기 바람 | K8: 20250530001046 | L8: https://dart.fss.or.kr/dsaf001/main.do?rcpNo=20250530001046
A9: 8 | B9: 45800 | C9: 2025 | D9: 코엔텍 | E9: 주권매매거래정지 (주식의 병합, 분할 등 전자등록 변경, 말소) | G9: 거래소공시(시장본부) | H9: 코스닥시장본부 | I9: Y | J9: 본 공시사항은 한국거래소 코스닥시장본부 소관임 | K9: 20250523900393 | L9: https://dart.fss.or.kr/dsaf001/main.do?rcpNo=20250523900393
A10: 9 | B10: 45792 | C10: 2025 | D10: 코엔텍 | E10: 분기보고서 (2025.03) | G10: 정기공시 | H10: 코엔텍 | I10: Y | K10: 20250515000316 | L10: https://dart.fss.or.kr/dsaf001/main.do?rcpNo=20250515000316
A11: 10 | B11: 45785 | C11: 2025 | D11: 코엔텍 | E11: 감자완료 | G11: 거래소공시(시장본부) | H11: 코엔텍 | I11: Y | J11: 본 공시사항은 한국거래소 코스닥시장본부 소관임 | K11: 20250508900692 | L11: https://dart.fss.or.kr/dsaf001/main.do?rcpNo=20250508900692
A12: 11 | B12: 45775 | C12: 2025 | D12: 코엔텍 | E12: 임시주주총회결과 | G12: 거래소공시(시장본부) | H12: 코엔텍 | I12: Y | J12: 본 공시사항은 한국거래소 코스닥시장본부 소관임 | K12: 20250428900298 | L12: https://dart.fss.or.kr/dsaf001/main.do?rcpNo=20250428900298
A13: 12 | B13: 45758 | C13: 2025 | D13: 코엔텍 | E13: 의결권대리행사권유참고서류 | G13: 지분공시 | H13: 코엔텍 | I13: Y | K13: 20250411001781 | L13: https://dart.fss.or.kr/dsaf001/main.do?rcpNo=20250411001781
A14: 13 | B14: 45758 | C14: 2025 | D14: 코엔텍 | E14: 주주총회소집공고 | G14: 거래소공시(수시공시) | H14: 코엔텍 | I14: Y | K14: 20250411001750 | L14: https://dart.fss.or.kr/dsaf001/main.do?rcpNo=20250411001750
A15: 14 | B15: 45747 | C15: 2025 | D15: 코엔텍 | E15: 정기주주총회결과 | G15: 거래소공시(시장본부) | H15: 코엔텍 | I15: Y | J15: 본 공시사항은 한국거래소 코스닥시장본부 소관임 | K15: 20250331901797 | L15: https://dart.fss.or.kr/dsaf001/main.do?rcpNo=20250331901797
A16: 15 | B16: 45737 | C16: 2025 | D16: 코엔텍 | E16: 감사보고서제출 | G16: 외부감사관련 | H16: 코엔텍 | I16: Y | J16: 본 공시사항은 한국거래소 코스닥시장본부 소관임 | K16: 20250321901569 | L16: https://dart.fss.or.kr/dsaf001/main.do?rcpNo=20250321901569
A17: 16 | B17: 45737 | C17: 2025 | D17: 코엔텍 | E17: 사업보고서 (2024.12) | G17: 정기공시 | H17: 코엔텍 | I17: Y | K17: 20250321001548 | L17: https://dart.fss.or.kr/dsaf001/main.do?rcpNo=20250321001548
A18: 17 | B18: 45736 | C18: 2025 | D18: 코엔텍 | E18: [기재정정] 최대주주변경을수반하는주식담보제공계약체결 | F18: 기재정정 | G18: 거래소공시(시장본부) | H18: 코엔텍 | I18: Y | J18: 본 공시사항은 한국거래소 코스닥시장본부 소관임 | K18: 20250320900162 | L18: https://dart.fss.or.kr/dsaf001/main.do?rcpNo=20250320900162
A19: 18 | B19: 45736 | C19: 2025 | D19: 코엔텍 | E19: [기재정정] 최대주주변경을수반하는주식담보제공계약해제ㆍ취소등 | F19: 기재정정 | G19: 거래소공시(시장본부) | H19: 코엔텍 | I19: Y | J19: 본 공시사항은 한국거래소 코스닥시장본부 소관임 | K19: 20250320900082 | L19: https://dart.fss.or.kr/dsaf001/main.do?rcpNo=20250320900082
A20: 19 | B20: 45735 | C20: 2025 | D20: 코엔텍 | E20: 최대주주변경을수반하는주식담보제공계약체결 | G20: 거래소공시(시장본부) | H20: 코엔텍 | I20: N | J20: 본 공시사항은 한국거래소 코스닥시장본부 소관임 | K20: 20250319901456 | L20: https://dart.fss.or.kr/dsaf001/main.do?rcpNo=20250319901456
A21: 20 | B21: 45735 | C21: 2025 | D21: 코엔텍 | E21: 최대주주변경을수반하는주식담보제공계약해제ㆍ취소등 | G21: 거래소공시(시장본부) | H21: 코엔텍 | I21: N | J21: 본 공시사항은 한국거래소 코스닥시장본부 소관임 | K21: 20250319901434 | L21: https://dart.fss.or.kr/dsaf001/main.do?rcpNo=20250319901434
A22: 21 | B22: 45735 | C22: 2025 | D22: 코엔텍 | E22: 임원ㆍ주요주주특정증권등소유상황보고서 | G22: 지분공시 | H22: 블랙사파이어홀딩스 | I22: Y | K22: 20250319000505 | L22: https://dart.fss.or.kr/dsaf001/main.do?rcpNo=20250319000505
A23: 22 | B23: 45735 | C23: 2025 | D23: 코엔텍 | E23: 임원ㆍ주요주주특정증권등소유상황보고서 | G23: 지분공시 | H23: 이앤아이홀딩스 | I23: Y | K23: 20250319000482 | L23: https://dart.fss.or.kr/dsaf001/main.do?rcpNo=20250319000482
A24: 23 | B24: 45735 | C24: 2025 | D24: 코엔텍 | E24: 주식등의대량보유상황보고서(일반) | G24: 지분공시 | H24: 이앤아이홀딩스 | I24: Y | K24: 20250319000469 | L24: https://dart.fss.or.kr/dsaf001/main.do?rcpNo=20250319000469
A25: 24 | B25: 45734 | C25: 2025 | D25: 코엔텍 | E25: 주권매매거래정지 (주식교환, 이전) | G25: 거래소공시(시장본부) | H25: 코스닥시장본부 | I25: Y | J25: 본 공시사항은 한국거래소 코스닥시장본부 소관임 | K25: 20250318900019 | L25: https://dart.fss.or.kr/dsaf001/main.do?rcpNo=20250318900019
A26: 25 | B26: 45734 | C26: 2025 | D26: 코엔텍 | E26: 주주총회소집결의 (임시주주총회) | G26: 거래소공시(시장본부) | H26: 코엔텍 | I26: Y | J26: 본 공시사항은 한국거래소 코스닥시장본부 소관임 | K26: 20250318900017 | L26: https://dart.fss.or.kr/dsaf001/main.do?rcpNo=20250318900017
A27: 26 | B27: 45734 | C27: 2025 | D27: 코엔텍 | E27: 주요사항보고서(주식교환ㆍ이전결정) | G27: 주요사항보고서 | H27: 코엔텍 | I27: Y | K27: 20250318000008 | L27: https://dart.fss.or.kr/dsaf001/main.do?rcpNo=20250318000008
A28: 27 | B28: 45733 | C28: 2025 | D28: 코엔텍 | E28: 주주명부폐쇄기간또는기준일설정 | G28: 거래소공시(시장본부) | H28: 코엔텍 | I28: Y | J28: 본 공시사항은 한국거래소 코스닥시장본부 소관임 | K28: 20250317901349 | L28: https://dart.fss.or.kr/dsaf001/main.do?rcpNo=20250317901349
A29: 28 | B29: 45730 | C29: 2025 | D29: 코엔텍 | E29: 의결권대리행사권유참고서류 | G29: 지분공시 | H29: 코엔텍 | I29: Y | K29: 20250314000465 | L29: https://dart.fss.or.kr/dsaf001/main.do?rcpNo=20250314000465
A30: 29 | B30: 45730 | C30: 2025 | D30: 코엔텍 | E30: 주주총회소집공고 | G30: 거래소공시(수시공시) | H30: 코엔텍 | I30: Y | K30: 20250314000461 | L30: https://dart.fss.or.kr/dsaf001/main.do?rcpNo=20250314000461
A31: 30 | B31: 45714 | C31: 2025 | D31: 코엔텍 | E31: [첨부정정] 주주총회소집결의 | F31: 첨부정정 | G31: 거래소공시(시장본부) | H31: 코엔텍 | I31: Y | J31: 본 공시사항은 한국거래소 코스닥시장본부 소관임 | K31: 20250226900206 | L31: https://dart.fss.or.kr/dsaf001/main.do?rcpNo=20250226900206
A32: 31 | B32: 45714 | C32: 2025 | D32: 코엔텍 | E32: 주요사항보고서(감자결정) | G32: 주요사항보고서 | H32: 코엔텍 | I32: Y | K32: 20250226001580 | L32: https://dart.fss.or.kr/dsaf001/main.do?rcpNo=20250226001580
A33: 32 | B33: 45713 | C33: 2025 | D33: 코엔텍 | E33: 주식소각결정 | G33: 거래소공시(시장본부) | H33: 코엔텍 | I33: Y | J33: 본 공시사항은 한국거래소 코스닥시장본부 소관임 | K33: 20250225901424 | L33: https://dart.fss.or.kr/dsaf001/main.do?rcpNo=20250225901424
A34: 33 | B34: 45713 | C34: 2025 | D34: 코엔텍 | E34: [첨부정정] 주주총회소집결의 | F34: 첨부정정 | G34: 거래소공시(시장본부) | H34: 코엔텍 | I34: N | J34: 본 공시사항은 한국거래소 코스닥시장본부 소관임 | K34: 20250225901423 | L34: https://dart.fss.or.kr/dsaf001/main.do?rcpNo=20250225901423
A35: 34 | B35: 45713 | C35: 2025 | D35: 코엔텍 | E35: [기재정정] 주주총회소집결의 | F35: 기재정정 | G35: 거래소공시(시장본부) | H35: 코엔텍 | I35: N | J35: 본 공시사항은 한국거래소 코스닥시장본부 소관임 | K35: 20250225901422 | L35: https://dart.fss.or.kr/dsaf001/main.do?rcpNo=20250225901422
A36: 35 | B36: 45707 | C36: 2025 | D36: 코엔텍 | E36: 주주총회소집결의 | G36: 거래소공시(시장본부) | H36: 코엔텍 | I36: N | J36: 본 공시사항은 한국거래소 코스닥시장본부 소관임 | K36: 20250219900721 | L36: https://dart.fss.or.kr/dsaf001/main.do?rcpNo=20250219900721
A37: 36 | B37: 45667 | C37: 2025 | D37: 코엔텍 | E37: 임원ㆍ주요주주특정증권등소유상황보고서 | G37: 지분공시 | H37: 블랙사파이어홀딩스 | I37: Y | K37: 20250110000276 | L37: https://dart.fss.or.kr/dsaf001/main.do?rcpNo=20250110000276
A38: 37 | B38: 45663 | C38: 2025 | D38: 코엔텍 | E38: 주식등의대량보유상황보고서(일반) | G38: 지분공시 | H38: 이앤아이홀딩스 | I38: Y | K38: 20250106000222 | L38: https://dart.fss.or.kr/dsaf001/main.do?rcpNo=20250106000222
A39: 38 | B39: 45659 | C39: 2025 | D39: 코엔텍 | E39: 임원ㆍ주요주주특정증권등소유상황보고서 | G39: 지분공시 | H39: 블랙사파이어홀딩스 | I39: Y | K39: 20250102000146 | L39: https://dart.fss.or.kr/dsaf001/main.do?rcpNo=20250102000146
A40: 39 | B40: 45646 | C40: 2024 | D40: 코엔텍 | E40: 임원ㆍ주요주주특정증권등소유상황보고서 | G40: 지분공시 | H40: 블랙사파이어홀딩스 | I40: Y | K40: 20241220000074 | L40: https://dart.fss.or.kr/dsaf001/main.do?rcpNo=20241220000074
...

Sheet 요약
A1: 코엔텍 DART 공시 요약
A3: 대상 회사 | B3: 코엔텍 (DART 고유번호 00197476 / 00331858)
A4: 검색 기준 | B4: DART 공시통합검색 > 회사명 '코엔텍' (전체 기간)
A5: 공시 기간 | B5: 2000.04.12 ~ 2026.03.30
A6: 전체 건수 | B6: 528
A7: 최종본 건수 | B7: 455
A8: 정정 전 원본(대체됨) | B8: 73
A9: 수집일 | B9: 2026-08-20
A10: 출처 | B10: https://dart.fss.or.kr/dsab007/main.do
A12: 공시유형별 건수
A13: 공시유형 | B13: 전체 | C13: 최종본
A14: 거래소공시(수시공시) | B14: =COUNTIF(전체공시!$G$2:$G$529,$A14) -> 56 | C14: =COUNTIFS(전체공시!$G$2:$G$529,$A14,전체공시!$I$2:$I$529,"Y") -> 51
A15: 거래소공시(시장본부) | B15: =COUNTIF(전체공시!$G$2:$G$529,$A15) -> 193 | C15: =COUNTIFS(전체공시!$G$2:$G$529,$A15,전체공시!$I$2:$I$529,"Y") -> 173
A16: 공정위공시 | B16: =COUNTIF(전체공시!$G$2:$G$529,$A16) -> 1 | C16: =COUNTIFS(전체공시!$G$2:$G$529,$A16,전체공시!$I$2:$I$529,"Y") -> 1
A17: 기타공시 | B17: =COUNTIF(전체공시!$G$2:$G$529,$A17) -> 31 | C17: =COUNTIFS(전체공시!$G$2:$G$529,$A17,전체공시!$I$2:$I$529,"Y") -> 22
A18: 발행공시 | B18: =COUNTIF(전체공시!$G$2:$G$529,$A18) -> 15 | C18: =COUNTIFS(전체공시!$G$2:$G$529,$A18,전체공시!$I$2:$I$529,"Y") -> 12
A19: 외부감사관련 | B19: =COUNTIF(전체공시!$G$2:$G$529,$A19) -> 34 | C19: =COUNTIFS(전체공시!$G$2:$G$529,$A19,전체공시!$I$2:$I$529,"Y") -> 32
A20: 정기공시 | B20: =COUNTIF(전체공시!$G$2:$G$529,$A20) -> 107 | C20: =COUNTIFS(전체공시!$G$2:$G$529,$A20,전체공시!$I$2:$I$529,"Y") -> 87
A21: 주요사항보고서 | B21: =COUNTIF(전체공시!$G$2:$G$529,$A21) -> 4 | C21: =COUNTIFS(전체공시!$G$2:$G$529,$A21,전체공시!$I$2:$I$529,"Y") -> 4
A22: 지분공시 | B22: =COUNTIF(전체공시!$G$2:$G$529,$A22) -> 87 | C22: =COUNTIFS(전체공시!$G$2:$G$529,$A22,전체공시!$I$2:$I$529,"Y") -> 73
A23: 합계 | B23: =SUM(B14:B22) -> 528 | C23: =SUM(C14:C22) -> 455
A26: 연도별 건수
A27: 연도 | B27: 전체 | C27: 최종본
A28: 2026 | B28: =COUNTIF(전체공시!$C$2:$C$529,$A28) -> 1 | C28: =COUNTIFS(전체공시!$C$2:$C$529,$A28,전체공시!$I$2:$I$529,"Y") -> 1
A29: 2025 | B29: =COUNTIF(전체공시!$C$2:$C$529,$A29) -> 37 | C29: =COUNTIFS(전체공시!$C$2:$C$529,$A29,전체공시!$I$2:$I$529,"Y") -> 31
A30: 2024 | B30: =COUNTIF(전체공시!$C$2:$C$529,$A30) -> 20 | C30: =COUNTIFS(전체공시!$C$2:$C$529,$A30,전체공시!$I$2:$I$529,"Y") -> 20
A31: 2023 | B31: =COUNTIF(전체공시!$C$2:$C$529,$A31) -> 16 | C31: =COUNTIFS(전체공시!$C$2:$C$529,$A31,전체공시!$I$2:$I$529,"Y") -> 12
A32: 2022 | B32: =COUNTIF(전체공시!$C$2:$C$529,$A32) -> 18 | C32: =COUNTIFS(전체공시!$C$2:$C$529,$A32,전체공시!$I$2:$I$529,"Y") -> 17
A33: 2021 | B33: =COUNTIF(전체공시!$C$2:$C$529,$A33) -> 12 | C33: =COUNTIFS(전체공시!$C$2:$C$529,$A33,전체공시!$I$2:$I$529,"Y") -> 11
A34: 2020 | B34: =COUNTIF(전체공시!$C$2:$C$529,$A34) -> 38 | C34: =COUNTIFS(전체공시!$C$2:$C$529,$A34,전체공시!$I$2:$I$529,"Y") -> 33
A35: 2019 | B35: =COUNTIF(전체공시!$C$2:$C$529,$A35) -> 40 | C35: =COUNTIFS(전체공시!$C$2:$C$529,$A35,전체공시!$I$2:$I$529,"Y") -> 31
A36: 2018 | B36: =COUNTIF(전체공시!$C$2:$C$529,$A36) -> 13 | C36: =COUNTIFS(전체공시!$C$2:$C$529,$A36,전체공시!$I$2:$I$529,"Y") -> 13
A37: 2017 | B37: =COUNTIF(전체공시!$C$2:$C$529,$A37) -> 47 | C37: =COUNTIFS(전체공시!$C$2:$C$529,$A37,전체공시!$I$2:$I$529,"Y") -> 39
A38: 2016 | B38: =COUNTIF(전체공시!$C$2:$C$529,$A38) -> 26 | C38: =COUNTIFS(전체공시!$C$2:$C$529,$A38,전체공시!$I$2:$I$529,"Y") -> 20
A39: 2015 | B39: =COUNTIF(전체공시!$C$2:$C$529,$A39) -> 15 | C39: =COUNTIFS(전체공시!$C$2:$C$529,$A39,전체공시!$I$2:$I$529,"Y") -> 15
... A54: 2000 | B54: =COUNTIF(전체공시!$C$2:$C$529,$A54) -> 1 | C54: =COUNTIFS(전체공시!$C$2:$C$529,$A54,전체공시!$I$2:$I$529,"Y") -> 1
A55: 합계 | B55: =SUM(B28:B54) -> 528 | C55: =SUM(C28:C54) -> 455
A57: ※ '최종본=N' 행은 이후 정정공시로 대체된 원본 보고서입니다 (전체공시 시트에서 회색 음영).
A58: ※ '공시유형'은 보고서명·제출인 기준으로 자동 분류한 값이며 DART 공식 분류가 아닙니다.
A59: ※ DART 검색은 1회 조회기간 10년 제한이 있어 4개 구간(1999~2006/2007~2014/2015~2022.6/2022.7~2026.8)으로 나누어 수집·중복제거했습니다.
